Workbook

Sheet MD
A1: JOBDESC | B1: TIPE UKER | C1: COMPLETENAME | D1: KELOMPOK JABATAN | E1: UNIT KERJA | F1: PADESC | G1: UNIT KERJA_2 | H1: CORP. TITLE | I1: PSADESC | J1: KODE BRANCH | K1: ESGDESC
A2: CUSTOMER SERVICE | B2: KC | C2: Elsa Sonya Carentina | D2: Customer Service | E2: KC ABUNJANI SIPIN | F2: Region 04 Palembang | G2: SEKSI OPERASIONAL & LAYANAN | H2: Associate | I2: KC Abunjani Sipin | J2: 606 | K2: Kontrak Teller/CS
A3: CUSTOMER SERVICE | B3: KC | C3: Dita Zahrah Asna | D3: Customer Service | E3: KC ABUNJANI SIPIN | F3: Region 04 Palembang | G3: SEKSI OPERASIONAL & LAYANAN | H3: Associate | I3: KC Abunjani Sipin | J3: 606 | K3: Kontrak Teller/CS
A4: TELLER | B4: KC | C4: Caecar Janu Dilaga | D4: Teller | E4: KC ABUNJANI SIPIN | F4: Region 04 Palembang | G4: SEKSI OPERASIONAL & LAYANAN | H4: Associate | I4: KC Abunjani Sipin | J4: 606 | K4: Peserta Magang
A5: TELLER | B5: KC | C5: Siti Nabilah Khairunnisa | D5: Teller | E5: KC ABUNJANI SIPIN | F5: Region 04 Palembang | G5: SEKSI OPERASIONAL & LAYANAN | H5: Associate | I5: KC Abunjani Sipin | J5: 606 | K5: Peserta Magang
A6: UNIVERSAL BANKER | B6: KC | C6: Gusti Riski Permata | D6: Universal Banker - KC/KCP/KK | E6: KC ABUNJANI SIPIN | F6: Region 04 Palembang | G6: SEKSI OPERASIONAL & LAYANAN | H6: Associate | I6: KC Abunjani Sipin | J6: 606 | K6: Kontrak Teller/CS
A7: CUSTOMER SERVICE | B7: UN | C7: Ananda Jihan | D7: Customer Service | E7: U_5630_SIMPANG KAWAT | F7: Region 04 Palembang | G7: UNIT SIMPANG KAWAT | H7: Associate | I7: KC Abunjani Sipin | J7: 5630 | K7: Kontrak Teller/CS
A8: CUSTOMER SERVICE | B8: UN | C8: Chastity Delania Daeli | D8: Customer Service | E8: U_7042_FATAHILAH | F8: Region 04 Palembang | G8: UNIT FATAHILAH | H8: Associate | I8: KC Abunjani Sipin | J8: 7042 | K8: Kontrak Teller/CS
A9: CUSTOMER SERVICE | B9: UN | C9: Elza Dwi Safitri | D9: Customer Service | E9: U_5631_SIMPANG RIMBO | F9: Region 04 Palembang | G9: UNIT SIMPANG RIMBO | H9: Associate | I9: KC Abunjani Sipin | J9: 5631 | K9: Kontrak Teller/CS
A10: CUSTOMER SERVICE | B10: UN | C10: Sri Puji Rahayu | D10: Customer Service | E10: U_5633_SULTAN THAHA | F10: Region 04 Palembang | G10: UNIT SULTAN THAHA | H10: Associate | I10: KC Abunjani Sipin | J10: 5633 | K10: Kontrak Teller/CS
A11: CUSTOMER SERVICE | B11: UN | C11: Elga Nurhavita | D11: Customer Service | E11: U_5714_MENDALO INDAH | F11: Region 04 Palembang | G11: UNIT MENDALO INDAH | H11: Associate | I11: KC Abunjani Sipin | J11: 5714 | K11: Kontrak Teller/CS
A12: CUSTOMER SERVICE | B12: UN | C12: Muhammad Rivaldo | D12: Customer Service | E12: U_7105_PETALING | F12: Region 04 Palembang | G12: UNIT PETALING | H12: Associate | I12: KC Abunjani Sipin | J12: 7105 | K12: Kontrak Teller/CS
A13: CUSTOMER SERVICE | B13: UN | C13: Widia Hastuti | D13: Customer Service | E13: U_7103_KASANG JAYA | F13: Region 04 Palembang | G13: UNIT KASANG JAYA | H13: Associate | I13: KC Abunjani Sipin | J13: 7103 | K13: Kontrak Teller/CS
... A895: TELLER | B895: UN | C895: Dwi Syalwah Safitri | D895: Teller | E895: U_5806_PASAR BAWAH | F895: Region 04 Palembang | G895: TERAS GANG KIMTING | H895: Associate | I895: KC Tanjung Pandan | J895: 5806 | K895: Peserta Magang

Sheet REKAP ALL
A1: No | B1: Kantor Cabang | C1: Formasi CS | D1: Pemenuhan | E1: GAP | G1: No | H1: Kantor Cabang | I1: Formasi Teller | J1: Pemenuhan | K1: GAP | M1: No | N1: Kantor Cabang | O1: Formasi UB | P1: Pemenuhan | Q1: GAP
A2: 1 | B2: KC Tanjung Pandan | C2: =VLOOKUP(B2,'F KANCA'!$D$4:$H$24,4,FALSE)+(VLOOKUP(B2,'REKAP Unit'!$A$4:$C$24,2,FALSE))+(VLOOKUP(B2,'REKAP KCP'!$A$4:$C$18,2,FALSE)) -> 16 | D2: =(VLOOKUP(B2,'F KANCA'!$D$4:$H$24,5,FALSE))+(VLOOKUP(B2,'REKAP Unit'!$A$4:$C$24,3,FALSE))+(VLOOKUP(B2,'REKAP KCP'!$A$4:$C$18,3,FALSE)) -> 16 | E2: =D2-C2 -> 0 | G2: 1 | H2: KC Tanjung Pandan | I2: =VLOOKUP(H2,'F KANCA'!$D$4:$K$24,7,FALSE)+(VLOOKUP(H2,'REKAP Unit'!$A$4:$F$24,5,FALSE))+(VLOOKUP(H2,'REKAP KCP'!$A$4:$F$18,5,FALSE)) -> 16 | J2: =VLOOKUP(H2,'F KANCA'!$D$4:$K$24,8,FALSE)+(VLOOKUP(H2,'REKAP Unit'!$A$4:$F$24,6,FALSE))+(VLOOKUP(H2,'REKAP KCP'!$A$4:$F$18,6,FALSE)) -> 16 | K2: =J2-I2 -> 0 | M2: 1 | N2: KC Tanjung Pandan | O2: =VLOOKUP(N2,'F KANCA'!$D$4:$N$24,10,FALSE) -> 2 | P2: =VLOOKUP(N2,'F KANCA'!$D$4:$N$24,11,FALSE) -> 1 | Q2: =P2-O2 -> -1
A3: 2 | B3: KC Sungai Liat | C3: =VLOOKUP(B3,'F KANCA'!$D$4:$H$24,4,FALSE)+(VLOOKUP(B3,'REKAP Unit'!$A$4:$C$24,2,FALSE))+(VLOOKUP(B3,'REKAP KCP'!$A$4:$C$18,2,FALSE)) -> 22 | D3: =(VLOOKUP(B3,'F KANCA'!$D$4:$H$24,5,FALSE))+(VLOOKUP(B3,'REKAP Unit'!$A$4:$C$24,3,FALSE))+(VLOOKUP(B3,'REKAP KCP'!$A$4:$C$18,3,FALSE)) -> 22 | E3: =D3-C3 -> 0 | G3: 2 | H3: KC Sungai Liat | I3: =VLOOKUP(H3,'F KANCA'!$D$4:$K$24,7,FALSE)+(VLOOKUP(H3,'REKAP Unit'!$A$4:$F$24,5,FALSE))+(VLOOKUP(H3,'REKAP KCP'!$A$4:$F$18,5,FALSE)) -> 22 | J3: =VLOOKUP(H3,'F KANCA'!$D$4:$K$24,8,FALSE)+(VLOOKUP(H3,'REKAP Unit'!$A$4:$F$24,6,FALSE))+(VLOOKUP(H3,'REKAP KCP'!$A$4:$F$18,6,FALSE)) -> 19 | K3: =J3-I3 -> -3 | M3: 2 | N3: KC Sungai Liat | O3: =VLOOKUP(N3,'F KANCA'!$D$4:$N$24,10,FALSE) -> 1 | P3: =VLOOKUP(N3,'F KANCA'!$D$4:$N$24,11,FALSE) -> 1 | Q3: =P3-O3 -> 0
A4: 3 | B4: KC Sekayu | C4: =VLOOKUP(B4,'F KANCA'!$D$4:$H$24,4,FALSE)+(VLOOKUP(B4,'REKAP Unit'!$A$4:$C$24,2,FALSE))+(VLOOKUP(B4,'REKAP KCP'!$A$4:$C$18,2,FALSE)) -> 29 | D4: =(VLOOKUP(B4,'F KANCA'!$D$4:$H$24,5,FALSE))+(VLOOKUP(B4,'REKAP Unit'!$A$4:$C$24,3,FALSE))+(VLOOKUP(B4,'REKAP KCP'!$A$4:$C$18,3,FALSE)) -> 28 | E4: =D4-C4 -> -1 | G4: 3 | H4: KC Sekayu | I4: =VLOOKUP(H4,'F KANCA'!$D$4:$K$24,7,FALSE)+(VLOOKUP(H4,'REKAP Unit'!$A$4:$F$24,5,FALSE))+(VLOOKUP(H4,'REKAP KCP'!$A$4:$F$18,5,FALSE)) -> 22 | J4: =VLOOKUP(H4,'F KANCA'!$D$4:$K$24,8,FALSE)+(VLOOKUP(H4,'REKAP Unit'!$A$4:$F$24,6,FALSE))+(VLOOKUP(H4,'REKAP KCP'!$A$4:$F$18,6,FALSE)) -> 22 | K4: =J4-I4 -> 0 | M4: 3 | N4: KC Sekayu | O4: =VLOOKUP(N4,'F KANCA'!$D$4:$N$24,10,FALSE) -> 2 | P4: =VLOOKUP(N4,'F KANCA'!$D$4:$N$24,11,FALSE) -> 1 | Q4: =P4-O4 -> -1
A5: 4 | B5: KC Sarolangun | C5: =VLOOKUP(B5,'F KANCA'!$D$4:$H$24,4,FALSE)+(VLOOKUP(B5,'REKAP Unit'!$A$4:$C$24,2,FALSE)) -> 14 | D5: =(VLOOKUP(B5,'F KANCA'!$D$4:$H$24,5,FALSE))+(VLOOKUP(B5,'REKAP Unit'!$A$4:$C$24,3,FALSE)) -> 12 | E5: =D5-C5 -> -2 | G5: 4 | H5: KC Sarolangun | I5: =VLOOKUP(H5,'F KANCA'!$D$4:$K$24,7,FALSE)+(VLOOKUP(H5,'REKAP Unit'!$A$4:$F$24,5,FALSE)) -> 13 | J5: =VLOOKUP(H5,'F KANCA'!$D$4:$K$24,8,FALSE)+(VLOOKUP(H5,'REKAP Unit'!$A$4:$F$24,6,FALSE)) -> 13 | K5: =J5-I5 -> 0 | M5: 4 | N5: KC Sarolangun | O5: =VLOOKUP(N5,'F KANCA'!$D$4:$N$24,10,FALSE) -> 1 | P5: =VLOOKUP(N5,'F KANCA'!$D$4:$N$24,11,FALSE) -> 0 | Q5: =P5-O5 -> -1
A6: 5 | B6: KC Rimbo Bujang | C6: =VLOOKUP(B6,'F KANCA'!$D$4:$H$24,4,FALSE)+(VLOOKUP(B6,'REKAP Unit'!$A$4:$C$24,2,FALSE))+(VLOOKUP(B6,'REKAP KCP'!$A$4:$C$18,2,FALSE)) -> 18 | D6: =(VLOOKUP(B6,'F KANCA'!$D$4:$H$24,5,FALSE))+(VLOOKUP(B6,'REKAP Unit'!$A$4:$C$24,3,FALSE))+(VLOOKUP(B6,'REKAP KCP'!$A$4:$C$18,3,FALSE)) -> 18 | E6: =D6-C6 -> 0 | G6: 5 | H6: KC Rimbo Bujang | I6: =VLOOKUP(H6,'F KANCA'!$D$4:$K$24,7,FALSE)+(VLOOKUP(H6,'REKAP Unit'!$A$4:$F$24,5,FALSE))+(VLOOKUP(H6,'REKAP KCP'!$A$4:$F$18,5,FALSE)) -> 14 | J6: =VLOOKUP(H6,'F KANCA'!$D$4:$K$24,8,FALSE)+(VLOOKUP(H6,'REKAP Unit'!$A$4:$F$24,6,FALSE))+(VLOOKUP(H6,'REKAP KCP'!$A$4:$F$18,6,FALSE)) -> 14 | K6: =J6-I6 -> 0 | M6: 5 | N6: KC Rimbo Bujang | O6: =VLOOKUP(N6,'F KANCA'!$D$4:$N$24,10,FALSE) -> 1 | P6: =VLOOKUP(N6,'F KANCA'!$D$4:$N$24,11,FALSE) -> 1 | Q6: =P6-O6 -> 0
A7: 6 | B7: KC Prabumulih | C7: =VLOOKUP(B7,'F KANCA'!$D$4:$H$24,4,FALSE)+(VLOOKUP(B7,'REKAP Unit'!$A$4:$C$24,2,FALSE))+(VLOOKUP(B7,'REKAP KCP'!$A$4:$C$18,2,FALSE)) -> 21 | D7: =(VLOOKUP(B7,'F KANCA'!$D$4:$H$24,5,FALSE))+(VLOOKUP(B7,'REKAP Unit'!$A$4:$C$24,3,FALSE))+(VLOOKUP(B7,'REKAP KCP'!$A$4:$C$18,3,FALSE)) -> 18 | E7: =D7-C7 -> -3 | G7: 6 | H7: KC Prabumulih | I7: =VLOOKUP(H7,'F KANCA'!$D$4:$K$24,7,FALSE)+(VLOOKUP(H7,'REKAP Unit'!$A$4:$F$24,5,FALSE))+(VLOOKUP(H7,'REKAP KCP'!$A$4:$F$18,5,FALSE)) -> 18 | J7: =VLOOKUP(H7,'F KANCA'!$D$4:$K$24,8,FALSE)+(VLOOKUP(H7,'REKAP Unit'!$A$4:$F$24,6,FALSE))+(VLOOKUP(H7,'REKAP KCP'!$A$4:$F$18,6,FALSE)) -> 17 | K7: =J7-I7 -> -1 | M7: 6 | N7: KC Prabumulih | O7: =VLOOKUP(N7,'F KANCA'!$D$4:$N$24,10,FALSE) -> 2 | P7: =VLOOKUP(N7,'F KANCA'!$D$4:$N$24,11,FALSE) -> 2 | Q7: =P7-O7 -> 0
A8: 7 | B8: KC Pangkal Pinang | C8: =VLOOKUP(B8,'F KANCA'!$D$4:$H$24,4,FALSE)+(VLOOKUP(B8,'REKAP Unit'!$A$4:$C$24,2,FALSE))+(VLOOKUP(B8,'REKAP KK'!$A$4:$C$7,2,FALSE))+(VLOOKUP(B8,'REKAP KCP'!$A$4:$C$18,2,FALSE)) -> 27 | D8: =(VLOOKUP(B8,'F KANCA'!$D$4:$H$24,5,FALSE))+(VLOOKUP(B8,'REKAP Unit'!$A$4:$C$24,3,FALSE))+(VLOOKUP(B8,'REKAP KK'!$A$4:$C$7,3,FALSE))+(VLOOKUP(B8,'REKAP KCP'!$A$4:$C$18,3,FALSE)) -> 26 | E8: =D8-C8 -> -1 | G8: 7 | H8: KC Pangkal Pinang | I8: =VLOOKUP(H8,'F KANCA'!$D$4:$K$24,7,FALSE)+(VLOOKUP(H8,'REKAP Unit'!$A$4:$F$24,5,FALSE))+(VLOOKUP(H8,'REKAP KCP'!$A$4:$F$18,5,FALSE))+VLOOKUP(H8,'REKAP KK'!A4:F7,5,FALSE) -> 25 | J8: =VLOOKUP(H8,'F KANCA'!$D$4:$K$24,8,FALSE)+(VLOOKUP(H8,'REKAP Unit'!$A$4:$F$24,6,FALSE))+(VLOOKUP(H8,'REKAP KCP'!$A$4:$F$18,6,FALSE))+(VLOOKUP(H8,'REKAP KK'!A4:F7,6,FALSE)) -> 26 | K8: =J8-I8 -> 1 | M8: 7 | N8: KC Pangkal Pinang | O8: =VLOOKUP(N8,'F KANCA'!$D$4:$N$24,10,FALSE) -> 2 | P8: =VLOOKUP(N8,'F KANCA'!$D$4:$N$24,11,FALSE) -> 1 | Q8: =P8-O8 -> -1
A9: 8 | B9: KC Palembang Sriwijaya | C9: =VLOOKUP(B9,'F KANCA'!$D$4:$H$24,4,FALSE)+(VLOOKUP(B9,'REKAP Unit'!$A$4:$C$24,2,FALSE))+(VLOOKUP(B9,'REKAP KCP'!$A$4:$C$18,2,FALSE)) -> 41 | D9: =(VLOOKUP(B9,'F KANCA'!$D$4:$H$24,5,FALSE))+(VLOOKUP(B9,'REKAP Unit'!$A$4:$C$24,3,FALSE))+(VLOOKUP(B9,'REKAP KCP'!$A$4:$C$18,3,FALSE)) -> 40 | E9: =D9-C9 -> -1 | G9: 8 | H9: KC Palembang Sriwijaya | I9: =VLOOKUP(H9,'F KANCA'!$D$4:$K$24,7,FALSE)+(VLOOKUP(H9,'REKAP Unit'!$A$4:$F$24,5,FALSE))+(VLOOKUP(H9,'REKAP KCP'!$A$4:$F$18,5,FALSE)) -> 24 | J9: =VLOOKUP(H9,'F KANCA'!$D$4:$K$24,8,FALSE)+(VLOOKUP(H9,'REKAP Unit'!$A$4:$F$24,6,FALSE))+(VLOOKUP(H9,'REKAP KCP'!$A$4:$F$18,6,FALSE)) -> 24 | K9: =J9-I9 -> 0 | M9: 8 | N9: KC Palembang Sriwijaya | O9: =VLOOKUP(N9,'F KANCA'!$D$4:$N$24,10,FALSE) -> 2 | P9: =VLOOKUP(N9,'F KANCA'!$D$4:$N$24,11,FALSE) -> 2 | Q9: =P9-O9 -> 0
A10: 9 | B10: KC Palembang A. Rivai | C10: =VLOOKUP(B10,'F KANCA'!$D$4:$H$24,4,FALSE)+(VLOOKUP(B10,'REKAP Unit'!$A$4:$C$24,2,FALSE))+(VLOOKUP(B10,'REKAP KK'!$A$4:$C$7,2,FALSE))+(VLOOKUP(B10,'REKAP KCP'!$A$4:$C$18,2,FALSE)) -> 36 | D10: =(VLOOKUP(B10,'F KANCA'!$D$4:$H$24,5,FALSE))+(VLOOKUP(B10,'REKAP Unit'!$A$4:$C$24,3,FALSE))+(VLOOKUP(B10,'REKAP KK'!$A$4:$C$7,3,FALSE))+(VLOOKUP(B10,'REKAP KCP'!$A$4:$C$18,3,FALSE)) -> 33 | E10: =D10-C10 -> -3 | G10: 9 | H10: KC Palembang A. Rivai | I10: =VLOOKUP(H10,'F KANCA'!$D$4:$K$24,7,FALSE)+(VLOOKUP(H10,'REKAP Unit'!$A$4:$F$24,5,FALSE))+(VLOOKUP(H10,'REKAP KCP'!$A$4:$F$18,5,FALSE))+(VLOOKUP(H10,'REKAP KK'!A4:F7,5,FALSE)) -> 31 | J10: =VLOOKUP(H10,'F KANCA'!$D$4:$K$24,8,FALSE)+(VLOOKUP(H10,'REKAP Unit'!$A$4:$F$24,6,FALSE))+(VLOOKUP(H10,'REKAP KCP'!$A$4:$F$18,6,FALSE))+(VLOOKUP(H10,'REKAP KK'!A4:F7,6,FALSE)) -> 31 | K10: =J10-I10 -> 0 | M10: 9 | N10: KC Palembang A. Rivai | O10: =VLOOKUP(N10,'F KANCA'!$D$4:$N$24,10,FALSE) -> 6 | P10: =VLOOKUP(N10,'F KANCA'!$D$4:$N$24,11,FALSE) -> 6 | Q10: =P10-O10 -> 0
A11: 10 | B11: KC Pagar Alam | C11: =VLOOKUP(B11,'F KANCA'!$D$4:$H$24,4,FALSE)+(VLOOKUP(B11,'REKAP Unit'!$A$4:$C$24,2,FALSE)) -> 11 | D11: =(VLOOKUP(B11,'F KANCA'!$D$4:$H$24,5,FALSE))+(VLOOKUP(B11,'REKAP Unit'!$A$4:$C$24,3,FALSE)) -> 11 | E11: =D11-C11 -> 0 | G11: 10 | H11: KC Pagar Alam | I11: =VLOOKUP(H11,'F KANCA'!$D$4:$K$24,7,FALSE)+(VLOOKUP(H11,'REKAP Unit'!$A$4:$F$24,5,FALSE)) -> 10 | J11: =VLOOKUP(H11,'F KANCA'!$D$4:$K$24,8,FALSE)+(VLOOKUP(H11,'REKAP Unit'!$A$4:$F$24,6,FALSE)) -> 10 | K11: =J11-I11 -> 0 | M11: 10 | N11: KC Pagar Alam | O11: =VLOOKUP(N11,'F KANCA'!$D$4:$N$24,10,FALSE) -> 1 | P11: =VLOOKUP(N11,'F KANCA'!$D$4:$N$24,11,FALSE) -> 1 | Q11: =P11-O11 -> 0
A12: 11 | B12: KC Muara Enim | C12: =VLOOKUP(B12,'F KANCA'!$D$4:$H$24,4,FALSE)+(VLOOKUP(B12,'REKAP Unit'!$A$4:$C$24,2,FALSE))+(VLOOKUP(B12,'REKAP KCP'!$A$4:$C$18,2,FALSE)) -> 22 | D12: =(VLOOKUP(B12,'F KANCA'!$D$4:$H$24,5,FALSE))+(VLOOKUP(B12,'REKAP Unit'!$A$4:$C$24,3,FALSE))+(VLOOKUP(B12,'REKAP KCP'!$A$4:$C$18,3,FALSE)) -> 24 | E12: =D12-C12 -> 2 | G12: 11 | H12: KC Muara Enim | I12: =VLOOKUP(H12,'F KANCA'!$D$4:$K$24,7,FALSE)+(VLOOKUP(H12,'REKAP Unit'!$A$4:$F$24,5,FALSE))+(VLOOKUP(H12,'REKAP KCP'!$A$4:$F$18,5,FALSE)) -> 19 | J12: =VLOOKUP(H12,'F KANCA'!$D$4:$K$24,8,FALSE)+(VLOOKUP(H12,'REKAP Unit'!$A$4:$F$24,6,FALSE))+(VLOOKUP(H12,'REKAP KCP'!$A$4:$F$18,6,FALSE)) -> 21 | K12: =J12-I12 -> 2 | M12: 11 | N12: KC Muara Enim | O12: =VLOOKUP(N12,'F KANCA'!$D$4:$N$24,10,FALSE) -> 2 | P12: =VLOOKUP(N12,'F KANCA'!$D$4:$N$24,11,FALSE) -> 2 | Q12: =P12-O12 -> 0
A13: 12 | B13: KC Muara Bungo | C13: =VLOOKUP(B13,'F KANCA'!$D$4:$H$24,4,FALSE)+(VLOOKUP(B13,'REKAP Unit'!$A$4:$C$24,2,FALSE)) -> 12 | D13: =(VLOOKUP(B13,'F KANCA'!$D$4:$H$24,5,FALSE))+(VLOOKUP(B13,'REKAP Unit'!$A$4:$C$24,3,FALSE)) -> 12 | E13: =D13-C13 -> 0 | G13: 12 | H13: KC Muara Bungo | I13: =VLOOKUP(H13,'F KANCA'!$D$4:$K$24,7,FALSE)+(VLOOKUP(H13,'REKAP Unit'!$A$4:$F$24,5,FALSE)) -> 13 | J13: =VLOOKUP(H13,'F KANCA'!$D$4:$K$24,8,FALSE)+(VLOOKUP(H13,'REKAP Unit'!$A$4:$F$24,6,FALSE)) -> 13 | K13: =J13-I13 -> 0 | M13: 12 | N13: KC Muara Bungo | O13: =VLOOKUP(N13,'F KANCA'!$D$4:$N$24,10,FALSE) -> 2 | P13: =VLOOKUP(N13,'F KANCA'!$D$4:$N$24,11,FALSE) -> 1 | Q13: =P13-O13 -> -1
A14: 13 | B14: KC Muara Bulian | C14: =VLOOKUP(B14,'F KANCA'!$D$4:$H$24,4,FALSE)+(VLOOKUP(B14,'REKAP Unit'!$A$4:$C$24,2,FALSE))+(VLOOKUP(B14,'REKAP KCP'!$A$4:$C$18,2,FALSE)) -> 20 | D14: =(VLOOKUP(B14,'F KANCA'!$D$4:$H$24,5,FALSE))+(VLOOKUP(B14,'REKAP Unit'!$A$4:$C$24,3,FALSE))+(VLOOKUP(B14,'REKAP KCP'!$A$4:$C$18,3,FALSE)) -> 20 | E14: =D14-C14 -> 0 | G14: 13 | H14: KC Muara Bulian | I14: =VLOOKUP(H14,'F KANCA'!$D$4:$K$24,7,FALSE)+(VLOOKUP(H14,'REKAP Unit'!$A$4:$F$24,5,FALSE))+(VLOOKUP(H14,'REKAP KCP'!$A$4:$F$18,5,FALSE)) -> 15 | J14: =VLOOKUP(H14,'F KANCA'!$D$4:$K$24,8,FALSE)+(VLOOKUP(H14,'REKAP Unit'!$A$4:$F$24,6,FALSE))+(VLOOKUP(H14,'REKAP KCP'!$A$4:$F$18,6,FALSE)) -> 15 | K14: =J14-I14 -> 0 | M14: 13 | N14: KC Muara Bulian | O14: =VLOOKUP(N14,'F KANCA'!$D$4:$N$24,10,FALSE) -> 1 | P14: =VLOOKUP(N14,'F KANCA'!$D$4:$N$24,11,FALSE) -> 1 | Q14: =P14-O14 -> 0
A15: 14 | B15: KC Lubuk Linggau | C15: =VLOOKUP(B15,'F KANCA'!$D$4:$H$24,4,FALSE)+(VLOOKUP(B15,'REKAP Unit'!$A$4:$C$24,2,FALSE)) -> 27 | D15: =(VLOOKUP(B15,'F KANCA'!$D$4:$H$24,5,FALSE))+(VLOOKUP(B15,'REKAP Unit'!$A$4:$C$24,3,FALSE)) -> 27 | E15: =D15-C15 -> 0 | G15: 14 | H15: KC Lubuk Linggau | I15: =VLOOKUP(H15,'F KANCA'!$D$4:$K$24,7,FALSE)+(VLOOKUP(H15,'REKAP Unit'!$A$4:$F$24,5,FALSE)) -> 19 | J15: =VLOOKUP(H15,'F KANCA'!$D$4:$K$24,8,FALSE)+(VLOOKUP(H15,'REKAP Unit'!$A$4:$F$24,6,FALSE)) -> 18 | K15: =J15-I15 -> -1 | M15: 14 | N15: KC Lubuk Linggau | O15: =VLOOKUP(N15,'F KANCA'!$D$4:$N$24,10,FALSE) -> 2 | P15: =VLOOKUP(N15,'F KANCA'!$D$4:$N$24,11,FALSE) -> 1 | Q15: =P15-O15 -> -1
A16: 15 | B16: KC Lahat | C16: =VLOOKUP(B16,'F KANCA'!$D$4:$H$24,4,FALSE)+(VLOOKUP(B16,'REKAP Unit'!$A$4:$C$24,2,FALSE))+(VLOOKUP(B16,'REKAP KCP'!$A$4:$C$18,2,FALSE)) -> 17 | D16: =(VLOOKUP(B16,'F KANCA'!$D$4:$H$24,5,FALSE))+(VLOOKUP(B16,'REKAP Unit'!$A$4:$C$24,3,FALSE))+(VLOOKUP(B16,'REKAP KCP'!$A$4:$C$18,3,FALSE)) -> 14 | E16: =D16-C16 -> -3 | G16: 15 | H16: KC Lahat | I16: =VLOOKUP(H16,'F KANCA'!$D$4:$K$24,7,FALSE)+(VLOOKUP(H16,'REKAP Unit'!$A$4:$F$24,5,FALSE))+(VLOOKUP(H16,'REKAP KCP'!$A$4:$F$18,5,FALSE)) -> 16 | J16: =VLOOKUP(H16,'F KANCA'!$D$4:$K$24,8,FALSE)+(VLOOKUP(H16,'REKAP Unit'!$A$4:$F$24,6,FALSE))+(VLOOKUP(H16,'REKAP KCP'!$A$4:$F$18,6,FALSE)) -> 17 | K16: =J16-I16 -> 1 | M16: 15 | N16: KC Lahat | O16: =VLOOKUP(N16,'F KANCA'!$D$4:$N$24,10,FALSE) -> 1 | P16: =VLOOKUP(N16,'F KANCA'!$D$4:$N$24,11,FALSE) -> 1 | Q16: =P16-O16 -> 0
A17: 16 | B17: KC Kuala Tungkal | C17: =VLOOKUP(B17,'F KANCA'!$D$4:$H$24,4,FALSE)+(VLOOKUP(B17,'REKAP Unit'!$A$4:$C$24,2,FALSE))+(VLOOKUP(B17,'REKAP KK'!$A$4:$C$7,2,FALSE))+(VLOOKUP(B17,'REKAP KCP'!$A$4:$C$18,2,FALSE)) -> 23 | D17: =(VLOOKUP(B17,'F KANCA'!$D$4:$H$24,5,FALSE))+(VLOOKUP(B17,'REKAP Unit'!$A$4:$C$24,3,FALSE))+(VLOOKUP(B17,'REKAP KCP'!$A$4:$C$18,3,FALSE))+(VLOOKUP(B17,'REKAP KK'!$A$4:$C$7,3,FALSE)) -> 24 | E17: =D17-C17 -> 1 | G17: 16 | H17: KC Kuala Tungkal | I17: =VLOOKUP(H17,'F KANCA'!$D$4:$K$24,7,FALSE)+(VLOOKUP(H17,'REKAP Unit'!$A$4:$F$24,5,FALSE))+(VLOOKUP(H17,'REKAP KCP'!$A$4:$F$18,5,FALSE))+(VLOOKUP(H17,'REKAP KK'!A4:F7,5,FALSE)) -> 20 | J17: =VLOOKUP(H17,'F KANCA'!$D$4:$K$24,8,FALSE)+(VLOOKUP(H17,'REKAP Unit'!$A$4:$F$24,6,FALSE))+(VLOOKUP(H17,'REKAP KCP'!$A$4:$F$18,6,FALSE))+(VLOOKUP(H17,'REKAP KK'!A4:F7,6,FALSE)) -> 20 | K17: =J17-I17 -> 0 | M17: 16 | N17: KC Kuala Tungkal | O17: =VLOOKUP(N17,'F KANCA'!$D$4:$N$24,10,FALSE) -> 2 | P17: =VLOOKUP(N17,'F KANCA'!$D$4:$N$24,11,FALSE) -> 1 | Q17: =P17-O17 -> -1
A18: 17 | B18: KC Kayu Agung | C18: =VLOOKUP(B18,'F KANCA'!$D$4:$H$24,4,FALSE)+(VLOOKUP(B18,'REKAP Unit'!$A$4:$C$24,2,FALSE))+(VLOOKUP(B18,'REKAP KCP'!$A$4:$C$18,2,FALSE)) -> 37 | D18: =(VLOOKUP(B18,'F KANCA'!$D$4:$H$24,5,FALSE))+(VLOOKUP(B18,'REKAP Unit'!$A$4:$C$24,3,FALSE))+(VLOOKUP(B18,'REKAP KCP'!$A$4:$C$18,3,FALSE)) -> 37 | E18: =D18-C18 -> 0 | G18: 17 | H18: KC Kayu Agung | I18: =VLOOKUP(H18,'F KANCA'!$D$4:$K$24,7,FALSE)+(VLOOKUP(H18,'REKAP Unit'!$A$4:$F$24,5,FALSE))+(VLOOKUP(H18,'REKAP KCP'!$A$4:$F$18,5,FALSE)) -> 30 | J18: =VLOOKUP(H18,'F KANCA'!$D$4:$K$24,8,FALSE)+(VLOOKUP(H18,'REKAP Unit'!$A$4:$F$24,6,FALSE))+(VLOOKUP(H18,'REKAP KCP'!$A$4:$F$18,6,FALSE)) -> 30 | K18: =J18-I18 -> 0 | M18: 17 | N18: KC Kayu Agung | O18: =VLOOKUP(N18,'F KANCA'!$D$4:$N$24,10,FALSE) -> 2 | P18: =VLOOKUP(N18,'F KANCA'!$D$4:$N$24,11,FALSE) -> 1 | Q18: =P18-O18 -> -1
A19: 18 | B19: KC Jambi | C19: =VLOOKUP(B19,'F KANCA'!$D$4:$H$24,4,FALSE)+(VLOOKUP(B19,'REKAP Unit'!$A$4:$C$24,2,FALSE))+(VLOOKUP(B19,'REKAP KK'!$A$4:$C$7,2,FALSE)) -> 23 | D19: =(VLOOKUP(B19,'F KANCA'!$D$4:$H$24,5,FALSE))+(VLOOKUP(B19,'REKAP Unit'!$A$4:$C$24,3,FALSE))+(VLOOKUP(B19,'REKAP KK'!$A$4:$C$7,3,FALSE))+(VLOOKUP(B19,'REKAP KCP'!$A$4:$C$18,3,FALSE)) -> 22 | E19: =D19-C19 -> -1 | G19: 18 | H19: KC Jambi | I19: =VLOOKUP(H19,'F KANCA'!$D$4:$K$24,7,FALSE)+(VLOOKUP(H19,'REKAP Unit'!$A$4:$F$24,5,FALSE))+(VLOOKUP(H19,'REKAP KCP'!$A$4:$F$18,5,FALSE))+(VLOOKUP(H19,'REKAP KK'!A4:F7,5,FALSE)) -> 20 | J19: =VLOOKUP(H19,'F KANCA'!$D$4:$K$24,8,FALSE)+(VLOOKUP(H19,'REKAP Unit'!$A$4:$F$24,6,FALSE))+(VLOOKUP(H19,'REKAP KCP'!$A$4:$F$18,6,FALSE))+(VLOOKUP(H19,'REKAP KK'!A4:F7,6,FALSE)) -> 18 | K19: =J19-I19 -> -2 | M19: 18 | N19: KC Jambi | O19: =VLOOKUP(N19,'F KANCA'!$D$4:$N$24,10,FALSE) -> 4 | P19: =VLOOKUP(N19,'F KANCA'!$D$4:$N$24,11,FALSE) -> 4 | Q19: =P19-O19 -> 0
A20: 19 | B20: KC Baturaja | C20: =VLOOKUP(B20,'F KANCA'!$D$4:$H$24,4,FALSE)+(VLOOKUP(B20,'REKAP Unit'!$A$4:$C$24,2,FALSE))+(VLOOKUP(B20,'REKAP KCP'!$A$4:$C$18,2,FALSE)) -> 36 | D20: =(VLOOKUP(B20,'F KANCA'!$D$4:$H$24,5,FALSE))+(VLOOKUP(B20,'REKAP Unit'!$A$4:$C$24,3,FALSE))+(VLOOKUP(B20,'REKAP KCP'!$A$4:$C$18,3,FALSE)) -> 34 | E20: =D20-C20 -> -2 | G20: 19 | H20: KC Baturaja | I20: =VLOOKUP(H20,'F KANCA'!$D$4:$K$24,7,FALSE)+(VLOOKUP(H20,'REKAP Unit'!$A$4:$F$24,5,FALSE))+(VLOOKUP(H20,'REKAP KCP'!$A$4:$F$18,5,FALSE)) -> 30 | J20: =VLOOKUP(H20,'F KANCA'!$D$4:$K$24,8,FALSE)+(VLOOKUP(H20,'REKAP Unit'!$A$4:$F$24,6,FALSE))+(VLOOKUP(H20,'REKAP KCP'!$A$4:$F$18,6,FALSE)) -> 30 | K20: =J20-I20 -> 0 | M20: 19 | N20: KC Baturaja | O20: =VLOOKUP(N20,'F KANCA'!$D$4:$N$24,10,FALSE) -> 2 | P20: =VLOOKUP(N20,'F KANCA'!$D$4:$N$24,11,FALSE) -> 1 | Q20: =P20-O20 -> -1
A21: 20 | B21: KC Bangko | C21: =VLOOKUP(B21,'F KANCA'!$D$4:$H$24,4,FALSE)+(VLOOKUP(B21,'REKAP Unit'!$A$4:$C$24,2,FALSE)) -> 17 | D21: =(VLOOKUP(B21,'F KANCA'!$D$4:$H$24,5,FALSE))+(VLOOKUP(B21,'REKAP Unit'!$A$4:$C$24,3,FALSE)) -> 16 | E21: =D21-C21 -> -1 | G21: 20 | H21: KC Bangko | I21: =VLOOKUP(H21,'F KANCA'!$D$4:$K$24,7,FALSE)+(VLOOKUP(H21,'REKAP Unit'!$A$4:$F$24,5,FALSE)) -> 14 | J21: =VLOOKUP(H21,'F KANCA'!$D$4:$K$24,8,FALSE)+(VLOOKUP(H21,'REKAP Unit'!$A$4:$F$24,6,FALSE)) -> 14 | K21: =J21-I21 -> 0 | M21: 20 | N21: KC Bangko | O21: =VLOOKUP(N21,'F KANCA'!$D$4:$N$24,10,FALSE) -> 1 | P21: =VLOOKUP(N21,'F KANCA'!$D$4:$N$24,11,FALSE) -> 1 | Q21: =P21-O21 -> 0
A22: 21 | B22: KC Abunjani Sipin | C22: =VLOOKUP(B22,'F KANCA'!$D$4:$H$24,4,FALSE)+(VLOOKUP(B22,'REKAP Unit'!$A$4:$C$24,2,FALSE)) -> 22 | D22: =(VLOOKUP(B22,'F KANCA'!$D$4:$H$24,5,FALSE))+(VLOOKUP(B22,'REKAP Unit'!$A$4:$C$24,3,FALSE)) -> 13 | E22: =D22-C22 -> -9 | G22: 21 | H22: KC Abunjani Sipin | I22: =VLOOKUP(H22,'F KANCA'!$D$4:$K$24,7,FALSE)+(VLOOKUP(H22,'REKAP Unit'!$A$4:$F$24,5,FALSE)) -> 12 | J22: =VLOOKUP(H22,'F KANCA'!$D$4:$K$24,8,FALSE)+(VLOOKUP(H22,'REKAP Unit'!$A$4:$F$24,6,FALSE)) -> 12 | K22: =J22-I22 -> 0 | M22: 21 | N22: KC Abunjani Sipin | O22: =VLOOKUP(N22,'F KANCA'!$D$4:$N$24,10,FALSE) -> 1 | P22: =VLOOKUP(N22,'F KANCA'!$D$4:$N$24,11,FALSE) -> 1 | Q22: =P22-O22 -> 0
A23: Total | C23: =SUM(C2:C22) -> 491 | D23: =SUM(D2:D22) -> 467 | E23: =SUM(E2:E22) -> -24 | G23: Total | I23: =SUM(I2:I22) -> 403 | J23: =SUM(J2:J22) -> 400 | K23: =SUM(K2:K22) -> -3 | M23: Total | O23: =SUM(O2:O22) -> 40 | P23: =SUM(P2:P22) -> 31 | Q23: =SUM(Q2:Q22) -> -9

Sheet F KANCA
A1: FORMASI JABATAN KANCA
A2: PERIODE :Jan 2025
A3: NO | B3: REGIONAL OFFICE | C3: KODE KANTOR CABANG | D3: KANTOR CABANG | E3: KELAS KANCA | F3: PERIODE | G3: Formasi Customer Service | H3: Existing | I3: GAP | J3: Formasi Teller | K3: Existing | L3: GAP | M3: Formasi UB | N3: Existing | O3: GAP
A4: 1 | B4: Palembang | C4: 131 | D4: KC Tanjung Pandan | E4: IIIA | F4: Jan 2025 | G4: 3 | H4: 3 | I4: =H4-G4 -> 0 | J4: 4 | K4: 4 | L4: =K4-J4 -> 0 | M4: 2 | N4: 1 | O4: =N4-M4 -> -1
A5: 2 | B5: Palembang | C5: 324 | D5: KC Sungai Liat | E5: IIIA | F5: Jan 2025 | G5: 2 | H5: 2 | I5: =H5-G5 -> 0 | J5: 3 | K5: 3 | L5: =K5-J5 -> 0 | M5: 1 | N5: 1 | O5: =N5-M5 -> 0
A6: 3 | B6: Palembang | C6: 164 | D6: KC Sekayu | E6: IIIA | F6: Jan 2025 | G6: 3 | H6: 4 | I6: =H6-G6 -> 1 | J6: 4 | K6: 4 | L6: =K6-J6 -> 0 | M6: 2 | N6: 1 | O6: =N6-M6 -> -1
A7: 4 | B7: Palembang | C7: 604 | D7: KC Sarolangun | E7: IIIB | F7: Jan 2025 | G7: 2 | H7: 3 | I7: =H7-G7 -> 1 | J7: 3 | K7: 3 | L7: =K7-J7 -> 0 | M7: 1 | N7: 0 | O7: =N7-M7 -> -1
A8: 5 | B8: Palembang | C8: 607 | D8: KC Rimbo Bujang | E8: IIIB | F8: Jan 2025 | G8: 2 | H8: 2 | I8: =H8-G8 -> 0 | J8: 2 | K8: 2 | L8: =K8-J8 -> 0 | M8: 1 | N8: 1 | O8: =N8-M8 -> 0
A9: 6 | B9: Palembang | C9: 184 | D9: KC Prabumulih | E9: IIIA | F9: Jan 2025 | G9: 2 | H9: 1 | I9: =H9-G9 -> -1 | J9: 4 | K9: 3 | L9: =K9-J9 -> -1 | M9: 2 | N9: 2 | O9: =N9-M9 -> 0
A10: 7 | B10: Palembang | C10: 63 | D10: KC Pangkal Pinang | E10: IIA | F10: Jan 2025 | G10: 5 | H10: 4 | I10: =H10-G10 -> -1 | J10: 4 | K10: 4 | L10: =K10-J10 -> 0 | M10: 2 | N10: 1 | O10: =N10-M10 -> -1
A11: 8 | B11: Palembang | C11: 342 | D11: KC Palembang Sriwijaya | E11: IB | F11: Jan 2025 | G11: 4 | H11: 3 | I11: =H11-G11 -> -1 | J11: 3 | K11: 4 | L11: =K11-J11 -> 1 | M11: 2 | N11: 2 | O11: =N11-M11 -> 0
A12: 9 | B12: Palembang | C12: 59 | D12: KC Palembang A. Rivai | E12: IA | F12: Jan 2025 | G12: 5 | H12: 4 | I12: =H12-G12 -> -1 | J12: 7 | K12: 7 | L12: =K12-J12 -> 0 | M12: 6 | N12: 6 | O12: =N12-M12 -> 0
A13: 10 | B13: Palembang | C13: 138 | D13: KC Pagar Alam | E13: IIIB | F13: Jan 2025 | G13: 2 | H13: 2 | I13: =H13-G13 -> 0 | J13: 3 | K13: 3 | L13: =K13-J13 -> 0 | M13: 1 | N13: 1 | O13: =N13-M13 -> 0
A14: 11 | B14: Palembang | C14: 128 | D14: KC Muara Enim | E14: IIIB | F14: Jan 2025 | G14: 2 | H14: 2 | I14: =H14-G14 -> 0 | J14: 3 | K14: 3 | L14: =K14-J14 -> 0 | M14: 2 | N14: 2 | O14: =N14-M14 -> 0
A15: 12 | B15: Palembang | C15: 160 | D15: KC Muara Bungo | E15: IIIA | F15: Jan 2025 | G15: 2 | H15: 2 | I15: =H15-G15 -> 0 | J15: 4 | K15: 4 | L15: =K15-J15 -> 0 | M15: 2 | N15: 1 | O15: =N15-M15 -> -1
... A24: 21 | B24: Palembang | C24: 606 | D24: KC Abunjani Sipin | E24: IIIB | F24: Jan 2025 | G24: 2 | H24: 2 | I24: =H24-G24 -> 0 | J24: 2 | K24: 2 | L24: =K24-J24 -> 0 | M24: 1 | N24: 1 | O24: =N24-M24 -> 0
G25: =SUM(G4:G24) -> 54 | H25: =SUM(H4:H24) -> 53 | I25: =SUM(I4:I24) -> -1 | J25: =SUM(J4:J24) -> 73 | K25: =SUM(K4:K24) -> 75 | L25: =SUM(L4:L24) -> 2 | M25: =SUM(M4:M24) -> 40 | N25: =SUM(N4:N24) -> 31 | O25: =SUM(O4:O24) -> -9

Sheet REKAP KCP
A3: Row Labels | B3: Sum of Formasi Customer Service | C3: Sum of Existing | D3: Sum of GAP | E3: Sum of Formasi Teller | F3: Sum of Existing2 | G3: Sum of GAP2
A4: KC Baturaja | B4: 3 | C4: 2 | D4: -1 | E4: 2 | F4: 2 | G4: 0
A5: KC Jambi | B5: 3 | C5: 3 | D5: 0 | E5: 2 | F5: 2 | G5: 0
A6: KC Kayu Agung | B6: 4 | C6: 4 | D6: 0 | E6: 2 | F6: 2 | G6: 0
A7: KC Kuala Tungkal | B7: 2 | C7: 2 | D7: 0 | E7: 2 | F7: 2 | G7: 0
A8: KC Lahat | B8: 1 | C8: 1 | D8: 0 | E8: 1 | F8: 1 | G8: 0
A9: KC Muara Bulian | B9: 1 | C9: 1 | D9: 0 | E9: 1 | F9: 1 | G9: 0
A10: KC Muara Enim | B10: 2 | C10: 2 | D10: 0 | E10: 1 | F10: 1 | G10: 0
A11: KC Palembang A. Rivai | B11: 3 | C11: 3 | D11: 0 | E11: 3 | F11: 3 | G11: 0
A12: KC Palembang Sriwijaya | B12: 10 | C12: 10 | D12: 0 | E12: 6 | F12: 6 | G12: 0
A13: KC Pangkal Pinang | B13: 3 | C13: 3 | D13: 0 | E13: 3 | F13: 3 | G13: 0
A14: KC Prabumulih | B14: 2 | C14: 2 | D14: 0 | E14: 1 | F14: 1 | G14: 0
A15: KC Rimbo Bujang | B15: 2 | C15: 2 | D15: 0 | E15: 1 | F15: 1 | G15: 0
... A19: Grand Total | B19: 43 | C19: 42 | D19: -1 | E19: 31 | F19: 31 | G19: 0

Sheet F KCP
A1: FORMASI JABATAN KCP
A2: PERIODE :Jan 2025
A3: NO | B3: REGIONAL OFFICE | C3: KODE KANTOR CABANG | D3: KANTOR CABANG | E3: KODE KCP | F3: CABANG PEMBANTU | G3: KELAS KCP | H3: PERIODE | I3: Formasi Customer Service | J3: Existing | K3: GAP | L3: Formasi Teller | M3: Existing | N3: GAP
A4: 1 | B4: Palembang | C4: 131 | D4: KC Tanjung Pandan | E4: 2093 | F4: KCP MANGGAR | G4: IIIA | H4: Jan 2025 | I4: 1 | J4: =VLOOKUP(E4,Sheet12!$A$5:$C$32,2,FALSE) -> 1 | K4: =J4-I4 -> 0 | L4: 2 | M4: =VLOOKUP(E4,Sheet12!$A$5:$C$32,3,FALSE) -> 2 | N4: =M4-L4 -> 0
A5: 2 | B5: Palembang | C5: 324 | D5: KC Sungai Liat | E5: 2145 | F5: KCP BELINYU | G5: IIIA | H5: Jan 2025 | I5: 1 | J5: =VLOOKUP(E5,Sheet12!$A$5:$C$32,2,FALSE) -> 1 | K5: =J5-I5 -> 0 | L5: 1 | M5: =VLOOKUP(E5,Sheet12!$A$5:$C$32,3,FALSE) -> 1 | N5: =M5-L5 -> 0
A6: 3 | B6: Palembang | C6: 164 | D6: KC Sekayu | E6: 670 | F6: KCP SUNGAI LILIN SEKAYU | G6: IIIA | H6: Jan 2025 | I6: 2 | J6: =VLOOKUP(E6,Sheet12!$A$5:$C$32,2,FALSE) -> 2 | K6: =J6-I6 -> 0 | L6: 1 | M6: =VLOOKUP(E6,Sheet12!$A$5:$C$32,3,FALSE) -> 1 | N6: =M6-L6 -> 0
A7: 4 | B7: Palembang | C7: 164 | D7: KC Sekayu | E7: 1100 | F7: KCP PANGKALAN BALAI | G7: IIIA | H7: Jan 2025 | I7: 2 | J7: =VLOOKUP(E7,Sheet12!$A$5:$C$32,2,FALSE) -> 2 | K7: =J7-I7 -> 0 | L7: 1 | M7: =VLOOKUP(E7,Sheet12!$A$5:$C$32,3,FALSE) -> 1 | N7: =M7-L7 -> 0
A8: 5 | B8: Palembang | C8: 607 | D8: KC Rimbo Bujang | E8: 2292 | F8: KCP Muara Tebo | G8: IIIB | H8: Jan 2025 | I8: 2 | J8: =VLOOKUP(E8,Sheet12!$A$5:$C$32,2,FALSE) -> 2 | K8: =J8-I8 -> 0 | L8: 1 | M8: =VLOOKUP(E8,Sheet12!$A$5:$C$32,3,FALSE) -> 1 | N8: =M8-L8 -> 0
A9: 6 | B9: Palembang | C9: 184 | D9: KC Prabumulih | E9: 2279 | F9: KCP PENDOPO | G9: IIIA | H9: Jan 2025 | I9: 2 | J9: =VLOOKUP(E9,Sheet12!$A$5:$C$32,2,FALSE) -> 2 | K9: =J9-I9 -> 0 | L9: 1 | M9: =VLOOKUP(E9,Sheet12!$A$5:$C$32,3,FALSE) -> 1 | N9: =M9-L9 -> 0
A10: 7 | B10: Palembang | C10: 63 | D10: KC Pangkal Pinang | E10: 2091 | F10: KCP TOBOALI | G10: IIA | H10: Jan 2025 | I10: 1 | J10: =VLOOKUP(E10,Sheet12!$A$5:$C$32,2,FALSE) -> 1 | K10: =J10-I10 -> 0 | L10: 1 | M10: =VLOOKUP(E10,Sheet12!$A$5:$C$32,3,FALSE) -> 1 | N10: =M10-L10 -> 0
A11: 8 | B11: Palembang | C11: 324 | D11: KC Sungai Liat | E11: 2090 | F11: KCP MENTOK | G11: IIIA | H11: Jan 2025 | I11: 1 | J11: =VLOOKUP(E11,Sheet12!$A$5:$C$32,2,FALSE) -> 1 | K11: =J11-I11 -> 0 | L11: 1 | M11: =VLOOKUP(E11,Sheet12!$A$5:$C$32,3,FALSE) -> 1 | N11: =M11-L11 -> 0
A12: 9 | B12: Palembang | C12: 63 | D12: KC Pangkal Pinang | E12: 2194 | F12: KCP KOBA | G12: IIA | H12: Jan 2025 | I12: 1 | J12: =VLOOKUP(E12,Sheet12!$A$5:$C$32,2,FALSE) -> 1 | K12: =J12-I12 -> 0 | L12: 1 | M12: =VLOOKUP(E12,Sheet12!$A$5:$C$32,3,FALSE) -> 1 | N12: =M12-L12 -> 0
A13: 10 | B13: Palembang | C13: 63 | D13: KC Pangkal Pinang | E13: 2193 | F13: KCP DEPATI AMIR | G13: IIA | H13: Jan 2025 | I13: 1 | J13: =VLOOKUP(E13,Sheet12!$A$5:$C$32,2,FALSE) -> 1 | K13: =J13-I13 -> 0 | L13: 1 | M13: =VLOOKUP(E13,Sheet12!$A$5:$C$32,3,FALSE) -> 1 | N13: =M13-L13 -> 0
A14: 11 | B14: Palembang | C14: 342 | D14: KC Palembang Sriwijaya | E14: 1103 | F14: KCP LEMABANG | G14: IB | H14: Jan 2025 | I14: 2 | J14: =VLOOKUP(E14,Sheet12!$A$5:$C$32,2,FALSE) -> 2 | K14: =J14-I14 -> 0 | L14: 1 | M14: =VLOOKUP(E14,Sheet12!$A$5:$C$32,3,FALSE) -> 1 | N14: =M14-L14 -> 0
A15: 12 | B15: Palembang | C15: 342 | D15: KC Palembang Sriwijaya | E15: 2206 | F15: KCP PASAR SAKO KENTEN | G15: IB | H15: Jan 2025 | I15: 2 | J15: =VLOOKUP(E15,Sheet12!$A$5:$C$32,2,FALSE) -> 2 | K15: =J15-I15 -> 0 | L15: 1 | M15: =VLOOKUP(E15,Sheet12!$A$5:$C$32,3,FALSE) -> 1 | N15: =M15-L15 -> 0
... A31: 28 | B31: Palembang | C31: 8 | D31: KC Baturaja | E31: 697 | F31: KCP GUMAWANG | G31: IIIA | H31: Jan 2025 | I31: 2 | J31: =VLOOKUP(E31,Sheet12!$A$5:$C$32,2,FALSE) -> 1 | K31: =J31-I31 -> -1 | L31: 1 | M31: =VLOOKUP(E31,Sheet12!$A$5:$C$32,3,FALSE) -> 1 | N31: =M31-L31 -> 0
I32: =SUM(I4:I31) -> 43 | J32: =SUM(J4:J31) -> 42 | K32: =SUM(K4:K31) -> -1 | L32: =SUM(L4:L31) -> 31 | M32: =SUM(M4:M31) -> 31 | N32: =SUM(N4:N31) -> 0

Sheet REKAP Unit
A3: Row Labels | B3: Sum of Formasi Customer Service Unit | C3: Sum of Existing | D3: Sum of GAP | E3: Sum of Formasi Teller Unit | F3: Sum of Existing2 | G3: Sum of GAP2
A4: KC Abunjani Sipin | B4: 20 | C4: 11 | D4: -9 | E4: 10 | F4: 10 | G4: 0
A5: KC Bangko | B5: 14 | C5: 13 | D5: -1 | E5: 11 | F5: 11 | G5: 0
A6: KC Baturaja | B6: 30 | C6: 28 | D6: -2 | E6: 24 | F6: 23 | G6: 0
A7: KC Jambi | B7: 19 | C7: 16 | D7: -3 | E7: 13 | F7: 11 | G7: -2
A8: KC Kayu Agung | B8: 31 | C8: 31 | D8: 0 | E8: 25 | F8: 25 | G8: 0
A9: KC Kuala Tungkal | B9: 19 | C9: 19 | D9: 0 | E9: 14 | F9: 14 | G9: 0
A10: KC Lahat | B10: 14 | C10: 11 | D10: -3 | E10: 12 | F10: 12 | G10: 0
A11: KC Lubuk Linggau | B11: 25 | C11: 25 | D11: 0 | E11: 15 | F11: 14 | G11: -1
A12: KC Muara Bulian | B12: 17 | C12: 17 | D12: 0 | E12: 11 | F12: 11 | G12: 0
A13: KC Muara Bungo | B13: 10 | C13: 10 | D13: 0 | E13: 9 | F13: 9 | G13: 0
A14: KC Muara Enim | B14: 18 | C14: 20 | D14: 2 | E14: 15 | F14: 17 | G14: 2
A15: KC Pagar Alam | B15: 9 | C15: 9 | D15: 0 | E15: 7 | F15: 7 | G15: 0
... A25: Grand Total | B25: 391 | C25: 367 | D25: -24 | E25: 290 | F25: 285 | G25: -4

Sheet F UNIT
A1: FORMASI JABATAN UNIT
A2: PERIODE :Jan 2025 | K2: FORMASI JABATAN UNIT-20-01-2025
A3: NO | B3: REGIONAL OFFICE | C3: KODE KANTOR CABANG | D3: KANTOR CABANG | E3: KODE UNIT | F3: TYPE UNIT | G3: UNIT/TERAS | H3: Formasi Customer Service Unit | I3: Existing | J3: GAP | K3: Formasi Teller Unit | L3: Existing | M3: GAP
A4: 1 | B4: Palembang | C4: 604 | D4: KC Sarolangun | E4: 8062 | G4: TERAS Tanah Abang | H4: 1 | I4: =VLOOKUP(E4,Sheet13!$A$5:$C$33,2,FALSE) -> 1 | J4: =I4-H4 -> 0 | K4: 1 | L4: =VLOOKUP(E4,Sheet13!$A$5:$C$33,3,FALSE) -> 1 | M4: =L4-K4 -> 0
A5: 2 | B5: Palembang | C5: 63 | D5: KC Pangkal Pinang | E5: 7142 | G5: TERAS Pasar Namang | H5: 1 | I5: =VLOOKUP(E5,Sheet13!$A$5:$C$33,2,FALSE) -> 1 | J5: =I5-H5 -> 0 | K5: 1 | L5: =VLOOKUP(E5,Sheet13!$A$5:$C$33,3,FALSE) -> 1 | M5: =L5-K5 -> 0
A6: 3 | B6: Palembang | C6: 131 | D6: KC Tanjung Pandan | E6: 5806 | G6: TERAS Pasar Gang Kimting | H6: 1 | I6: =VLOOKUP(E6,Sheet13!$A$5:$C$33,2,FALSE) -> 1 | J6: =I6-H6 -> 0 | K6: 1 | L6: =VLOOKUP(E6,Sheet13!$A$5:$C$33,3,FALSE) -> 1 | M6: =L6-K6 -> 0
A7: 4 | B7: Palembang | C7: 342 | D7: KC Palembang Sriwijaya | E7: 5788 | G7: TERAS Pasar Tanjung Siapi Api | H7: 1 | I7: =VLOOKUP(E7,Sheet13!$A$5:$C$33,2,FALSE) -> 1 | J7: =I7-H7 -> 0 | K7: 1 | L7: =VLOOKUP(E7,Sheet13!$A$5:$C$33,3,FALSE) -> 1 | M7: =L7-K7 -> 0
A8: 5 | B8: Palembang | C8: 63 | D8: KC Pangkal Pinang | E8: 5765 | G8: TERAS Pasar Pagi Pangkal Pinang | H8: 1 | I8: =VLOOKUP(E8,Sheet13!$A$5:$C$33,2,FALSE) -> 1 | J8: =I8-H8 -> 0 | K8: 1 | L8: =VLOOKUP(E8,Sheet13!$A$5:$C$33,3,FALSE) -> 1 | M8: =L8-K8 -> 0
A9: 6 | B9: Palembang | C9: 63 | D9: KC Pangkal Pinang | E9: 5764 | G9: TERAS Pasar Lubuk Besar | H9: 1 | I9: =VLOOKUP(E9,Sheet13!$A$5:$C$33,2,FALSE) -> 1 | J9: =I9-H9 -> 0 | K9: 1 | L9: =VLOOKUP(E9,Sheet13!$A$5:$C$33,3,FALSE) -> 1 | M9: =L9-K9 -> 0
A10: 7 | B10: Palembang | C10: 342 | D10: KC Palembang Sriwijaya | E10: 5761 | G10: TERAS Pasar Sako | H10: 1 | I10: =VLOOKUP(E10,Sheet13!$A$5:$C$33,2,FALSE) -> 1 | J10: =I10-H10 -> 0 | K10: 1 | L10: =VLOOKUP(E10,Sheet13!$A$5:$C$33,3,FALSE) -> 1 | M10: =L10-K10 -> 0
A11: 8 | B11: Palembang | C11: 342 | D11: KC Palembang Sriwijaya | E11: 5739 | G11: TERAS Pasar Talang Jambe | H11: 1 | I11: =VLOOKUP(E11,Sheet13!$A$5:$C$33,2,FALSE) -> 1 | J11: =I11-H11 -> 0 | K11: 1 | L11: =VLOOKUP(E11,Sheet13!$A$5:$C$33,3,FALSE) -> 1 | M11: =L11-K11 -> 0
A12: 9 | B12: Palembang | C12: 138 | D12: KC Pagar Alam | E12: 5736 | G12: TERAS Pasar Nendagung | H12: 1 | I12: =VLOOKUP(E12,Sheet13!$A$5:$C$33,2,FALSE) -> 1 | J12: =I12-H12 -> 0 | K12: 1 | L12: =VLOOKUP(E12,Sheet13!$A$5:$C$33,3,FALSE) -> 1 | M12: =L12-K12 -> 0
A13: 10 | B13: Palembang | C13: 128 | D13: KC Muara Enim | E13: 5732 | G13: TERAS Pasar Tanjung Enim | H13: 1 | I13: =VLOOKUP(E13,Sheet13!$A$5:$C$33,2,FALSE) -> 1 | J13: =I13-H13 -> 0 | K13: 1 | L13: =VLOOKUP(E13,Sheet13!$A$5:$C$33,3,FALSE) -> 1 | M13: =L13-K13 -> 0
A14: 11 | B14: Palembang | C14: 128 | D14: KC Muara Enim | E14: 5730 | G14: TERAS Pasar Muara Harapan | H14: 1 | I14: =VLOOKUP(E14,Sheet13!$A$5:$C$33,2,FALSE) -> 2 | J14: =I14-H14 -> 1 | K14: 1 | L14: =VLOOKUP(E14,Sheet13!$A$5:$C$33,3,FALSE) -> 2 | M14: =L14-K14 -> 1
A15: 12 | B15: Palembang | C15: 128 | D15: KC Muara Enim | E15: 5730 | G15: TERAS Pasar Ujan Mas | H15: 1 | I15: =VLOOKUP(E15,Sheet13!$A$5:$C$33,2,FALSE) -> 2 | J15: =I15-H15 -> 1 | K15: 1 | L15: =VLOOKUP(E15,Sheet13!$A$5:$C$33,3,FALSE) -> 2 | M15: =L15-K15 -> 1
... A19: 16 | B19: Palembang | C19: 607 | D19: KC Rimbo Bujang | E19: 5725 | G19: TERAS Simpang Niam | H19: 1 | I19: =VLOOKUP(E19,Sheet13!$A$5:$C$33,2,FALSE) -> 1 | J19: =I19-H19 -> 0 | K19: 1 | L19: =VLOOKUP(E19,Sheet13!$A$5:$C$33,3,FALSE) -> 1 | M19: =L19-K19 -> 0
A20: 17 | B20: Palembang | C20: 160 | D20: KC Muara Bungo | E20: 5724 | G20: TERAS Pasar Atas Jambi | H20: 0 | I20: 0 | J20: =I20-H20 -> 0 | K20: 0 | L20: 0 | M20: =L20-K20 -> 0
A21: 18 | B21: Palembang | C21: 129 | D21: KC Lubuk Linggau | E21: 5683 | G21: TERAS Pasar Inpres | H21: 0 | I21: 0 | J21: =I21-H21 -> 0 | K21: 0 | L21: 0 | M21: =L21-K21 -> 0 | N21: Tutup
A22: 19 | B22: Palembang | C22: 40 | D22: KC Lahat | E22: 5675 | G22: TERAS Pasar Ptm Square | H22: 1 | I22: =VLOOKUP(E22,Sheet13!$A$5:$C$33,2,FALSE) -> 0 | J22: =I22-H22 -> -1 | K22: 1 | L22: =VLOOKUP(E22,Sheet13!$A$5:$C$33,3,FALSE) -> 1 | M22: =L22-K22 -> 0
A23: 20 | B23: Palembang | C23: 179 | D23: KC Kuala Tungkal | E23: 5669 | G23: TERAS Pasar TPI | H23: 0 | I23: 0 | J23: =I23-H23 -> 0 | K23: 0 | L23: 0 | M23: =L23-K23 -> 0
A24: 21 | B24: Palembang | C24: 20 | D24: KC Jambi | E24: 5634 | G24: TERAS Pasar Baru Talang Banjar | H24: 0 | I24: 0 | J24: =I24-H24 -> 0 | K24: 0 | L24: 0 | M24: =L24-K24 -> 0
A25: 22 | B25: Palembang | C25: 20 | D25: KC Jambi | E25: 5628 | G25: TERAS Pasar Induk Angso Duo | H25: 1 | I25: =VLOOKUP(E25,Sheet13!$A$5:$C$33,2,FALSE) -> 0 | J25: =I25-H25 -> -1 | K25: 1 | L25: =VLOOKUP(E25,Sheet13!$A$5:$C$33,3,FALSE) -> 1 | M25: =L25-K25 -> 0
A26: 23 | B26: Palembang | C26: 8 | D26: KC Baturaja | E26: 5611 | G26: TERAS Pasar Martapura Oku | H26: 1 | I26: =VLOOKUP(E26,Sheet13!$A$5:$C$33,2,FALSE) -> 1 | J26: =I26-H26 -> 0 | K26: 1 | L26: =VLOOKUP(E26,Sheet13!$A$5:$C$33,3,FALSE) -> 1 | M26: =L26-K26 -> 0
A27: 24 | B27: Palembang | C27: 8 | D27: KC Baturaja | E27: 5609 | G27: TERAS Pasar Sidorahayu | H27: 1 | I27: =VLOOKUP(E27,Sheet13!$A$5:$C$33,2,FALSE) -> 1 | J27: =I27-H27 -> 0 | K27: 1 | L27: =VLOOKUP(E27,Sheet13!$A$5:$C$33,3,FALSE) -> 1 | M27: =L27-K27 -> 0
A28: 25 | B28: Palembang | C28: 8 | D28: KC Baturaja | E28: 5605 | G28: TERAS Pasar Unit 6 Oku Timur | H28: 1 | I28: =VLOOKUP(E28,Sheet13!$A$5:$C$33,2,FALSE) -> 1 | J28: =I28-H28 -> 0 | K28: 1 | L28: =VLOOKUP(E28,Sheet13!$A$5:$C$33,3,FALSE) -> 1 | M28: =L28-K28 -> 0
A29: 26 | B29: Palembang | C29: 604 | D29: KC Sarolangun | E29: 5604 | G29: TERAS Pasar Singkut | H29: 1 | I29: =VLOOKUP(E29,Sheet13!$A$5:$C$33,2,FALSE) -> 1 | J29: =I29-H29 -> 0 | K29: 1 | L29: =VLOOKUP(E29,Sheet13!$A$5:$C$33,3,FALSE) -> 1 | M29: =L29-K29 -> 0
A30: 27 | B30: Palembang | C30: 275 | D30: KC Bangko | E30: 5602 | G30: TERAS Pasar SPC | H30: 0 | I30: 0 | J30: =I30-H30 -> 0 | K30: 0 | L30: 0 | M30: =L30-K30 -> 0
A31: 28 | B31: Palembang | C31: 184 | D31: KC Prabumulih | E31: 3557 | G31: TERAS Pasar Pendopo | H31: 0 | I31: 0 | J31: =I31-H31 -> 0 | K31: 0 | L31: 0 | M31: =L31-K31 -> 0
A32: 29 | B32: Palembang | C32: 607 | D32: KC Rimbo Bujang | E32: 3554 | G32: TERAS Pasar Muara Tebo | H32: 1 | I32: =VLOOKUP(E32,Sheet13!$A$5:$C$33,2,FALSE) -> 1 | J32: =I32-H32 -> 0 | K32: 1 | L32: =VLOOKUP(E32,Sheet13!$A$5:$C$33,3,FALSE) -> 1 | M32: =L32-K32 -> 0
A33: 30 | B33: Palembang | C33: 40 | D33: KC Lahat | E33: 3550 | G33: TERAS Pasar Ilir | H33: 1 | I33: =VLOOKUP(E33,Sheet13!$A$5:$C$33,2,FALSE) -> 1 | J33: =I33-H33 -> 0 | K33: 1 | L33: =VLOOKUP(E33,Sheet13!$A$5:$C$33,3,FALSE) -> 1 | M33: =L33-K33 -> 0
A34: 31 | B34: Palembang | C34: 63 | D34: KC Pangkal Pinang | E34: 3397 | G34: TERAS Pasar Pasir Putih | H34: 1 | I34: =VLOOKUP(E34,Sheet13!$A$5:$C$33,2,FALSE) -> 1 | J34: =I34-H34 -> 0 | K34: 1 | L34: =VLOOKUP(E34,Sheet13!$A$5:$C$33,3,FALSE) -> 1 | M34: =L34-K34 -> 0
A35: 32 | B35: Palembang | C35: 607 | D35: KC Rimbo Bujang | E35: 3395 | G35: TERAS Pasar Sarinah Rimbo Bujang | H35: 1 | I35: =VLOOKUP(E35,Sheet13!$A$5:$C$33,2,FALSE) -> 1 | J35: =I35-H35 -> 0 | K35: 1 | L35: =VLOOKUP(E35,Sheet13!$A$5:$C$33,3,FALSE) -> 1 | M35: =L35-K35 -> 0
A36: 33 | B36: Palembang | C36: 40 | D36: KC Lahat | E36: 3393 | G36: TERAS Kavling | H36: 1 | I36: =VLOOKUP(E36,Sheet13!$A$5:$C$33,2,FALSE) -> 1 | J36: =I36-H36 -> 0 | K36: 1 | L36: =VLOOKUP(E36,Sheet13!$A$5:$C$33,3,FALSE) -> 1 | M36: =L36-K36 -> 0
A37: 34 | B37: Palembang | C37: 275 | D37: KC Bangko | E37: 3388 | G37: TERAS Pasar Baru Bangko | H37: 1 | I37: =VLOOKUP(E37,Sheet13!$A$5:$C$33,2,FALSE) -> 1 | J37: =I37-H37 -> 0 | K37: 1 | L37: =VLOOKUP(E37,Sheet13!$A$5:$C$33,3,FALSE) -> 1 | M37: =L37-K37 -> 0
A38: 35 | B38: Palembang | C38: 604 | D38: KC Sarolangun | E38: 3373 | G38: TERAS Pasar Sarolangun | H38: 1 | I38: =VLOOKUP(E38,Sheet13!$A$5:$C$33,2,FALSE) -> 1 | J38: =I38-H38 -> 0 | K38: 1 | L38: =VLOOKUP(E38,Sheet13!$A$5:$C$33,3,FALSE) -> 1 | M38: =L38-K38 -> 0
A39: 36 | B39: Palembang | C39: 8 | D39: KC Baturaja | E39: 3286 | G39: TERAS Pasar Baru Baturaja | H39: 1 | I39: =VLOOKUP(E39,Sheet13!$A$5:$C$33,2,FALSE) -> 1 | J39: =I39-H39 -> 0 | K39: 1 | L39: =VLOOKUP(E39,Sheet13!$A$5:$C$33,3,FALSE) -> 1 | M39: =L39-K39 -> 0
A40: 37 | B40: Palembang | C40: 342 | D40: KC Palembang Sriwijaya | E40: 7043 | G40: UNIT SIMPANG POLDA PALEMBANG S | H40: 0 | I40: 0 | J40: =I40-H40 -> 0 | K40: 0 | L40: 0 | M40: =L40-K40 -> 0
A41: 38 | B41: Palembang | C41: 59 | D41: KC Palembang A. Rivai | E41: 7017 | G41: UNIT POLYGON PALEMBANG A RIVAI | H41: 0 | I41: 0 | J41: =I41-H41 -> 0 | K41: 0 | L41: 0 | M41: =L41-K41 -> 0
A42: 39 | B42: Palembang | C42: 59 | D42: KC Palembang A. Rivai | E42: 5759 | G42: UNIT UNSRI PALEMBANG A RIVAI | H42: 0 | I42: 0 | J42: =I42-H42 -> 0 | K42: 0 | L42: 0 | M42: =L42-K42 -> 0
A43: 40 | B43: Palembang | C43: 342 | D43: KC Palembang Sriwijaya | E43: 5741 | G43: UNIT M. ISA PALEMBANG S | H43: 0 | I43: 0 | J43: =I43-H43 -> 0 | K43: 0 | L43: 0 | M43: =L43-K43 -> 0
...

Sheet REKAP KK
A3: Row Labels | B3: Sum of Formasi Customer Service | C3: Sum of Existing | D3: Sum of GAP | E3: Sum of Formasi Teller | F3: Sum of Existing2 | G3: Sum of GAP2
A4: KC Jambi | B4: 1 | C4: 1 | D4: 0 | E4: 1 | F4: 1 | G4: 0
A5: KC Kuala Tungkal | B5: 1 | C5: 1 | D5: 0 | E5: 1 | F5: 1 | G5: 0
A6: KC Palembang A. Rivai | B6: 3 | C6: 3 | D6: 0 | E6: 4 | F6: 4 | G6: 0
A7: KC Pangkal Pinang | B7: 1 | C7: 0 | D7: -1 | E7: 3 | F7: 3 | G7: 0
A8: Grand Total | B8: 6 | C8: 5 | D8: -1 | E8: 9 | F8: 9 | G8: 0

Sheet F KK
A1: FORMASI JABATAN KK
A2: PERIODE :Jan 2025
A3: NO | B3: REGIONAL OFFICE | C3: KODE KANTOR CABANG | D3: KANTOR CABANG | E3: KODE KK | F3: KANTOR KAS | G3: PERIODE | H3: Formasi Customer Service | I3: Existing | J3: GAP | K3: Formasi Teller | L3: Existing | M3: GAP
A4: 1 | B4: Palembang | C4: 63 | D4: KC Pangkal Pinang | E4: 1676 | F4: KK TASPEN PANGKALPINANG | G4: Sep 2026 | H4: 0 | I4: 0 | J4: =I4-H4 -> 0 | K4: 1 | L4: 1 | M4: =L4-K4 -> 0
A5: 2 | B5: Palembang | C5: 63 | D5: KC Pangkal Pinang | E5: 1670 | F5: KK RUMAH SAKIT BAKTI TIMAH | G5: Sep 2026 | H5: 0 | I5: 0 | J5: =I5-H5 -> 0 | K5: 1 | L5: 1 | M5: =L5-K5 -> 0
A6: 3 | B6: Palembang | C6: 63 | D6: KC Pangkal Pinang | E6: 1707 | F6: KK BANGKA TRADE CENTER | G6: Sep 2026 | H6: 1 | I6: 0 | J6: =I6-H6 -> -1 | K6: 1 | L6: 1 | M6: =L6-K6 -> 0
A7: 4 | B7: Palembang | C7: 59 | D7: KC Palembang A. Rivai | E7: 1863 | F7: KK RS PERTAMINA PLAJU | G7: Sep 2026 | H7: 1 | I7: 1 | J7: =I7-H7 -> 0 | K7: 1 | L7: 1 | M7: =L7-K7 -> 0
A8: 5 | B8: Palembang | C8: 59 | D8: KC Palembang A. Rivai | E8: 1304 | F8: KK RS CHARITAS | G8: Sep 2026 | H8: 1 | I8: 1 | J8: =I8-H8 -> 0 | K8: 1 | L8: 1 | M8: =L8-K8 -> 0
A9: 6 | B9: Palembang | C9: 59 | D9: KC Palembang A. Rivai | E9: 1887 | F9: KK PUSRI | G9: Sep 2026 | H9: 0 | I9: 0 | J9: =I9-H9 -> 0 | K9: 1 | L9: 1 | M9: =L9-K9 -> 0
A10: 7 | B10: Palembang | C10: 59 | D10: KC Palembang A. Rivai | E10: 1500 | F10: KK POLTABES PALEMBANG | G10: Sep 2026 | H10: 1 | I10: 1 | J10: =I10-H10 -> 0 | K10: 1 | L10: 1 | M10: =L10-K10 -> 0
A11: 8 | B11: Palembang | C11: 179 | D11: KC Kuala Tungkal | E11: 1487 | F11: KK PEMATANG LUMUT | G11: Sep 2026 | H11: 1 | I11: 1 | J11: =I11-H11 -> 0 | K11: 1 | L11: 1 | M11: =L11-K11 -> 0
A12: 9 | B12: Palembang | C12: 20 | D12: KC Jambi | E12: 1679 | F12: KK POLTABES JAMBI | G12: Sep 2026 | H12: 1 | I12: 1 | J12: =I12-H12 -> 0 | K12: 1 | L12: 1 | M12: =L12-K12 -> 0
H13: =SUM(H4:H12) -> 6 | I13: =SUM(I4:I12) -> 5 | J13: =SUM(J4:J12) -> -1 | K13: =SUM(K4:K12) -> 9 | L13: =SUM(L4:L12) -> 9 | M13: =SUM(M4:M12) -> 0

Sheet Sheet11
A3: Count of JOBDESC | B3: Column Labels
A4: Row Labels | B4: CUSTOMER SERVICE | C4: TELLER | D4: TELLER (H) | E4: UNIVERSAL BANKER | F4: Grand Total
A5: 8 | B5: 4 | C5: 4 | D5: 1 | E5: 1 | F5: 10
A6: 20 | B6: 2 | C6: 4 | E6: 4 | F6: 10
A7: 30 | B7: 2 | C7: 3 | E7: 1 | F7: 6
A8: 40 | B8: 2 | C8: 3 | D8: 1 | E8: 1 | F8: 7
A9: 59 | B9: 4 | C9: 7 | E9: 6 | F9: 17
A10: 63 | B10: 4 | C10: 4 | E10: 1 | F10: 9
A11: 128 | B11: 2 | C11: 3 | E11: 2 | F11: 7
A12: 129 | B12: 2 | C12: 4 | E12: 1 | F12: 7
A13: 131 | B13: 3 | C13: 4 | E13: 1 | F13: 8
A14: 138 | B14: 2 | C14: 3 | E14: 1 | F14: 6
A15: 160 | B15: 2 | C15: 4 | E15: 1 | F15: 7
A16: 164 | B16: 4 | C16: 4 | E16: 1 | F16: 9
A17: 179 | B17: 2 | C17: 3 | E17: 1 | F17: 6
A18: 184 | B18: 1 | C18: 3 | E18: 2 | F18: 6
A19: 275 | B19: 3 | C19: 3 | E19: 1 | F19: 7
A20: 315 | B20: 2 | C20: 3 | E20: 1 | F20: 6
... A22: 342 | B22: 3 | C22: 4 | E22: 2 | F22: 9
A23: 604 | B23: 3 | C23: 3 | F23: 6
A24: 606 | B24: 2 | C24: 2 | E24: 1 | F24: 5
A25: 607 | B25: 2 | C25: 2 | E25: 1 | F25: 5
A26: Grand Total | B26: 53 | C26: 73 | D26: 2 | E26: 31 | F26: 159

Sheet KC
A1: KODE BRANCH | B1: JOBDESC | C1: PERNR | D1: TIPE UKER | E1: COMPLETENAME | F1: KELOMPOK JABATAN | G1: MCTEXT | H1: PSADESC | I1: ESGDESC
A2: 606 | B2: CUSTOMER SERVICE | C2: 379367 | D2: KC | E2: Elsa Sonya Carentina | F2: Customer Service | G2: KC ABUNJANI SIPIN | H2: KC Abunjani Sipin | I2: Kontrak Teller/CS
A3: 606 | B3: CUSTOMER SERVICE | C3: 393712 | D3: KC | E3: Dita Zahrah Asna | F3: Customer Service | G3: KC ABUNJANI SIPIN | H3: KC Abunjani Sipin | I3: Kontrak Teller/CS
A4: 606 | B4: TELLER | C4: 413039 | D4: KC | E4: Caecar Janu Dilaga | F4: Teller | G4: KC ABUNJANI SIPIN | H4: KC Abunjani Sipin | I4: Peserta Magang
A5: 606 | B5: TELLER | C5: 413242 | D5: KC | E5: Siti Nabilah Khairunnisa | F5: Teller | G5: KC ABUNJANI SIPIN | H5: KC Abunjani Sipin | I5: Peserta Magang
A6: 606 | B6: UNIVERSAL BANKER | C6: 341871 | D6: KC | E6: Gusti Riski Permata | F6: Universal Banker - KC/KCP/KK | G6: KC ABUNJANI SIPIN | H6: KC Abunjani Sipin | I6: Kontrak Teller/CS
A7: 275 | B7: CUSTOMER SERVICE | C7: 359715 | D7: KC | E7: Agness Alifiana | F7: Customer Service | G7: KC BANGKO | H7: KC Bangko | I7: Kontrak Teller/CS
A8: 275 | B8: CUSTOMER SERVICE | C8: 366663 | D8: KC | E8: Indah Sari Mawardah | F8: Customer Service | G8: KC BANGKO | H8: KC Bangko | I8: Kontrak Teller/CS
A9: 275 | B9: CUSTOMER SERVICE | C9: 375483 | D9: KC | E9: Feby Savva Kharisma | F9: Customer Service | G9: KC BANGKO | H9: KC Bangko | I9: Kontrak Teller/CS
A10: 275 | B10: TELLER | C10: 392496 | D10: KC | E10: Zella Andhira | F10: Teller | G10: KC BANGKO | H10: KC Bangko | I10: Peserta Magang
A11: 275 | B11: TELLER | C11: 404603 | D11: KC | E11: Aini Cahya Adela | F11: Teller | G11: KC BANGKO | H11: KC Bangko | I11: Kontrak Teller/CS
A12: 275 | B12: TELLER | C12: 406882 | D12: KC | E12: Putri Ratu Heika | F12: Teller | G12: KC BANGKO | H12: KC Bangko | I12: Peserta Magang
A13: 275 | B13: UNIVERSAL BANKER | C13: 344836 | D13: KC | E13: Anggi Thamrin | F13: Universal Banker - KC/KCP/KK | G13: KC BANGKO | H13: KC Bangko | I13: Kontrak Teller/CS
... A160: 131 | B160: UNIVERSAL BANKER | C160: 341603 | D160: KC | E160: Januarti Silviani | F160: Universal Banker - KC/KCP/KK | G160: KC TANJUNG PANDAN | H160: KC Tanjung Pandan | I160: Kontrak Teller/CS

Sheet Sheet12
A3: Count of JOBDESC | B3: Column Labels
A4: Row Labels | B4: CUSTOMER SERVICE | C4: TELLER | D4: (blank) | E4: Grand Total
A5: 670 | B5: 2 | C5: 1 | E5: 3
A6: 697 | B6: 1 | C6: 1 | E6: 2
A7: 1001 | B7: 1 | C7: 1 | E7: 2
A8: 1100 | B8: 2 | C8: 1 | E8: 3
A9: 1102 | B9: 2 | C9: 1 | E9: 3
A10: 1103 | B10: 2 | C10: 1 | E10: 3
A11: 1104 | B11: 1 | C11: 1 | E11: 2
A12: 2015 | B12: 2 | C12: 1 | E12: 3
A13: 2076 | B13: 1 | C13: 1 | E13: 2
A14: 2088 | B14: 2 | C14: 1 | E14: 3
A15: 2089 | B15: 2 | C15: 1 | E15: 3
A16: 2090 | B16: 1 | C16: 1 | E16: 2
... A32: 2292 | B32: 2 | C32: 1 | E32: 3
A33: (blank)
A34: Grand Total | B34: 42 | C34: 31 | E34: 73

Sheet KCP
A1: NIP | B1: JOBDESC | C1: PERNR | D1: TIPE UKER | E1: COMPLETENAME | F1: KELOMPOK JABATAN | G1: MCTEXT | H1: PADESC | I1: ORGDESC | J1: CORP. TITLE | K1: PSADESC | L1: KODE BRANCH | M1: ESGDESC
A2: - | B2: CUSTOMER SERVICE | C2: 404621 | D2: KCP | E2: Padelito | F2: Customer Service | G2: KCP GUMAWANG | H2: Region 04 Palembang | I2: FUNGSI OPERASIONAL & LAYANAN | J2: Associate | K2: KC Baturaja | L2: 697 | M2: Kontrak Teller/CS
A3: 0 | B3: TELLER | C3: 398627 | D3: KCP | E3: Cindy Nov Melenia | F3: Teller | G3: KCP GUMAWANG | H3: Region 04 Palembang | I3: FUNGSI OPERASIONAL & LAYANAN | J3: Associate | K3: KC Baturaja | L3: 697 | M3: Peserta Magang
A4: K495840124 | B4: CUSTOMER SERVICE | C4: 371022 | D4: KCP | E4: Dandi Putratama | F4: Customer Service | G4: KCP MARTAPURA | H4: Region 04 Palembang | I4: FUNGSI OPERASIONAL & LAYANAN | J4: Associate | K4: KC Baturaja | L4: 2263 | M4: Kontrak Teller/CS
A5: 0 | B5: TELLER | C5: 404674 | D5: KCP | E5: Ines Rattri Puji Lestari | F5: Teller | G5: KCP MARTAPURA | H5: Region 04 Palembang | I5: FUNGSI OPERASIONAL & LAYANAN | J5: Associate | K5: KC Baturaja | L5: 2263 | M5: Peserta Magang
A6: - | B6: CUSTOMER SERVICE | C6: 401631 | D6: KCP | E6: Nuskiya Faradisa | F6: Customer Service | G6: KCP BATANGHARI | H6: Region 04 Palembang | I6: FUNGSI OPERASIONAL & LAYANAN | J6: Associate | K6: KC Jambi | L6: 2277 | M6: Kontrak Teller/CS
A7: 0 | B7: TELLER | C7: 408918 | D7: KCP | E7: Syifaniya Azzahra | F7: Teller | G7: KCP BATANGHARI | H7: Region 04 Palembang | I7: FUNGSI OPERASIONAL & LAYANAN | J7: Associate | K7: KC Jambi | L7: 2277 | M7: Peserta Magang
A8: K621310125 | B8: CUSTOMER SERVICE | C8: 392452 | D8: KCP | E8: Aurelia Angela Siregar | F8: Customer Service | G8: KCP JELUTUNG | H8: Region 04 Palembang | I8: FUNGSI OPERASIONAL & LAYANAN | J8: Associate | K8: KC Jambi | L8: 2015 | M8: Kontrak Teller/CS
A9: - | B9: CUSTOMER SERVICE | C9: 400052 | D9: KCP | E9: Mayzca Tanezia Putri | F9: Customer Service | G9: KCP JELUTUNG | H9: Region 04 Palembang | I9: FUNGSI OPERASIONAL & LAYANAN | J9: Associate | K9: KC Jambi | L9: 2015 | M9: Kontrak Teller/CS
A10: M333980325 | B10: TELLER | C10: 392655 | D10: KCP | E10: Ranti Asmanita | F10: Teller | G10: KCP JELUTUNG | H10: Region 04 Palembang | I10: FUNGSI OPERASIONAL & LAYANAN | J10: Associate | K10: KC Jambi | L10: 2015 | M10: Peserta Magang
A11: K316629723 | B11: CUSTOMER SERVICE | C11: 340773 | D11: KCP | E11: Nazza Miftahul Jannah | F11: Customer Service | G11: KCP INDRALAYA | H11: Region 04 Palembang | I11: FUNGSI OPERASIONAL & LAYANAN | J11: Associate | K11: KC Kayu Agung | L11: 2272 | M11: Kontrak Teller/CS
A12: K534750125 | B12: CUSTOMER SERVICE | C12: 379508 | D12: KCP | E12: Amelia Miranda | F12: Customer Service | G12: KCP INDRALAYA | H12: Region 04 Palembang | I12: FUNGSI OPERASIONAL & LAYANAN | J12: Associate | K12: KC Kayu Agung | L12: 2272 | M12: Kontrak Teller/CS
A13: - | B13: TELLER | C13: 396820 | D13: KCP | E13: Dewari Nandita Virginia | F13: Teller | G13: KCP INDRALAYA | H13: Region 04 Palembang | I13: FUNGSI OPERASIONAL & LAYANAN | J13: Associate | K13: KC Kayu Agung | L13: 2272 | M13: Kontrak Teller/CS
A14: K248869823 | B14: CUSTOMER SERVICE | C14: 332918 | D14: KCP | E14: Nada Triyani | F14: Customer Service | G14: KCP TUGUMULYO | H14: Region 04 Palembang | I14: FUNGSI OPERASIONAL & LAYANAN | J14: Associate | K14: KC Kayu Agung | L14: 2088 | M14: Kontrak Teller/CS
A15: K497859924 | B15: CUSTOMER SERVICE | C15: 371690 | D15: KCP | E15: Shinta Bella T. B | F15: Customer Service | G15: KCP TUGUMULYO | H15: Region 04 Palembang | I15: FUNGSI OPERASIONAL & LAYANAN | J15: Associate | K15: KC Kayu Agung | L15: 2088 | M15: Kontrak Teller/CS
A16: M288390125 | B16: TELLER | C16: 379455 | D16: KCP | E16: Ridho Kurniatullah | F16: Teller | G16: KCP TUGUMULYO | H16: Region 04 Palembang | I16: FUNGSI OPERASIONAL & LAYANAN | J16: Associate | K16: KC Kayu Agung | L16: 2088 | M16: Peserta Magang
A17: K508289924 | B17: CUSTOMER SERVICE | C17: 373581 | D17: KCP | E17: Sari Dwi Kartika | F17: Customer Service | G17: KCP TANJUNG JABUNG TIMUR | H17: Region 04 Palembang | I17: FUNGSI OPERASIONAL & LAYANAN | J17: Associate | K17: KC Kuala Tungkal | L17: 2207 | M17: Kontrak Teller/CS
A18: - | B18: CUSTOMER SERVICE | C18: 405306 | D18: KCP | E18: Muhammad Baihaqy | F18: Customer Service | G18: KCP TANJUNG JABUNG TIMUR | H18: Region 04 Palembang | I18: FUNGSI OPERASIONAL & LAYANAN | J18: Associate | K18: KC Kuala Tungkal | L18: 2207 | M18: Kontrak Teller/CS
A19: M305190125 | B19: TELLER | C19: 385347 | D19: KCP | E19: Eca Riska Viola | F19: Teller | G19: KCP TANJUNG JABUNG TIMUR | H19: Region 04 Palembang | I19: FUNGSI OPERASIONAL & LAYANAN | J19: Associate | K19: KC Kuala Tungkal | L19: 2207 | M19: Peserta Magang
A20: 0 | B20: TELLER | C20: 412864 | D20: KCP | E20: Yashifa Suci Rama | F20: Teller | G20: KCP TANJUNG JABUNG TIMUR | H20: Region 04 Palembang | I20: FUNGSI OPERASIONAL & LAYANAN | J20: Associate | K20: KC Kuala Tungkal | L20: 2207 | M20: Peserta Magang
A21: K603650025 | B21: CUSTOMER SERVICE | C21: 388713 | D21: KCP | E21: Eriko Kurniawan | F21: Customer Service | G21: KCP TEBING TINGGI | H21: Region 04 Palembang | I21: FUNGSI OPERASIONAL & LAYANAN | J21: Associate | K21: KC Lahat | L21: 2076 | M21: Kontrak Teller/CS
A22: M325780225 | B22: TELLER | C22: 389607 | D22: KCP | E22: Msy Anisa Ripanda | F22: Teller | G22: KCP TEBING TINGGI | H22: Region 04 Palembang | I22: FUNGSI OPERASIONAL & LAYANAN | J22: Associate | K22: KC Lahat | L22: 2076 | M22: Peserta Magang
A23: K614950125 | B23: CUSTOMER SERVICE | C23: 391128 | D23: KCP | E23: Maria Risnawati | F23: Customer Service | G23: KCP SUNGAI BAHAR | H23: Region 04 Palembang | I23: FUNGSI OPERASIONAL & LAYANAN | J23: Associate | K23: KC Muara Bulian | L23: 2239 | M23: Kontrak Teller/CS
A24: M289420125 | B24: TELLER | C24: 380141 | D24: KCP | E24: Khairani Fatihah | F24: Teller | G24: KCP SUNGAI BAHAR | H24: Region 04 Palembang | I24: FUNGSI OPERASIONAL & LAYANAN | J24: Associate | K24: KC Muara Bulian | L24: 2239 | M24: Peserta Magang
A25: K319139923 | B25: CUSTOMER SERVICE | C25: 341601 | D25: KCP | E25: Nadia Putri Maghfira | F25: Customer Service | G25: KCP TANJUNG ENIM | H25: Region 04 Palembang | I25: FUNGSI OPERASIONAL & LAYANAN | J25: Associate | K25: KC Muara Enim | L25: 1102 | M25: Kontrak Teller/CS
A26: K621000225 | B26: CUSTOMER SERVICE | C26: 392408 | D26: KCP | E26: Itra Juasari | F26: Customer Service | G26: KCP TANJUNG ENIM | H26: Region 04 Palembang | I26: FUNGSI OPERASIONAL & LAYANAN | J26: Associate | K26: KC Muara Enim | L26: 1102 | M26: Kontrak Teller/CS
A27: K620990125 | B27: TELLER | C27: 392407 | D27: KCP | E27: Mutiara Putri | F27: Teller | G27: KCP TANJUNG ENIM | H27: Region 04 Palembang | I27: FUNGSI OPERASIONAL & LAYANAN | J27: Associate | K27: KC Muara Enim | L27: 1102 | M27: Kontrak Teller/CS
A28: K442479924 | B28: CUSTOMER SERVICE | C28: 362086 | D28: KCP | E28: Siska Juwita | F28: Customer Service | G28: KCP AMPERA | H28: Region 04 Palembang | I28: FUNGSI OPERASIONAL & LAYANAN | J28: Associate | K28: KC Palembang A. Rivai | L28: 2278 | M28: Kontrak Teller/CS
A29: 0 | B29: TELLER | C29: 409245 | D29: KCP | E29: Siti Safirah Salsabila | F29: Teller | G29: KCP AMPERA | H29: Region 04 Palembang | I29: FUNGSI OPERASIONAL & LAYANAN | J29: Associate | K29: KC Palembang A. Rivai | L29: 2278 | M29: Kontrak Teller/CS
A30: K403400123 | B30: CUSTOMER SERVICE | C30: 351470 | D30: KCP | E30: Yuniarti | F30: Customer Service | G30: KCP DEMANG | H30: Region 04 Palembang | I30: FUNGSI OPERASIONAL & LAYANAN | J30: Associate | K30: KC Palembang A. Rivai | L30: 1104 | M30: Kontrak Teller/CS
A31: K512869924 | B31: TELLER | C31: 373721 | D31: KCP | E31: Cantika Diva Ramadina | F31: Teller | G31: KCP DEMANG | H31: Region 04 Palembang | I31: FUNGSI OPERASIONAL & LAYANAN | J31: Associate | K31: KC Palembang A. Rivai | L31: 1104 | M31: Kontrak Teller/CS
A32: K249029923 | B32: CUSTOMER SERVICE | C32: 334941 | D32: KCP | E32: Sintiya Nur Aliza | F32: Customer Service | G32: KCP ISKANDAR | H32: Region 04 Palembang | I32: FUNGSI OPERASIONAL & LAYANAN | J32: Associate | K32: KC Palembang A. Rivai | L32: 1001 | M32: Kontrak Teller/CS
A33: M297270325 | B33: TELLER | C33: 382688 | D33: KCP | E33: Oktaviani Dea Ananda Putri | F33: Teller | G33: KCP ISKANDAR | H33: Region 04 Palembang | I33: FUNGSI OPERASIONAL & LAYANAN | J33: Associate | K33: KC Palembang A. Rivai | L33: 1001 | M33: Peserta Magang
A34: 0 | B34: CUSTOMER SERVICE | C34: 409372 | D34: KCP | E34: Hervani Pratiwi | F34: Customer Service | G34: KCP KM 12 | H34: Region 04 Palembang | I34: FUNGSI OPERASIONAL & LAYANAN | J34: Associate | K34: KC Palembang Sriwijaya | L34: 2174 | M34: Kontrak Teller/CS
A35: 0 | B35: CUSTOMER SERVICE | C35: 413510 | D35: KCP | E35: Dwita Ayu Larasati | F35: Customer Service | G35: KCP KM 12 | H35: Region 04 Palembang | I35: FUNGSI OPERASIONAL & LAYANAN | J35: Associate | K35: KC Palembang Sriwijaya | L35: 2174 | M35: Kontrak Teller/CS
A36: M297370325 | B36: TELLER | C36: 382811 | D36: KCP | E36: Nasywa Shafa Chania | F36: Teller | G36: KCP KM 12 | H36: Region 04 Palembang | I36: FUNGSI OPERASIONAL & LAYANAN | J36: Associate | K36: KC Palembang Sriwijaya | L36: 2174 | M36: Peserta Magang
A37: 0 | B37: TELLER | C37: 406387 | D37: KCP | E37: Muhamad Tsamirul Qolbi | F37: Teller | G37: KCP KM 12 | H37: Region 04 Palembang | I37: FUNGSI OPERASIONAL & LAYANAN | J37: Associate | K37: KC Palembang Sriwijaya | L37: 2174 | M37: Peserta Magang
A38: K173989923 | B38: CUSTOMER SERVICE | C38: 328637 | D38: KCP | E38: Virgin Regina Aryani | F38: Customer Service | G38: KCP KM 5 | H38: Region 04 Palembang | I38: FUNGSI OPERASIONAL & LAYANAN | J38: Associate | K38: KC Palembang Sriwijaya | L38: 2205 | M38: Kontrak Teller/CS
A39: K512830024 | B39: CUSTOMER SERVICE | C39: 373717 | D39: KCP | E39: Olivia Paramitha Putriyani | F39: Customer Service | G39: KCP KM 5 | H39: Region 04 Palembang | I39: FUNGSI OPERASIONAL & LAYANAN | J39: Associate | K39: KC Palembang Sriwijaya | L39: 2205 | M39: Kontrak Teller/CS
A40: 0 | B40: TELLER | C40: 413516 | D40: KCP | E40: Yulia Putri | F40: Teller | G40: KCP KM 5 | H40: Region 04 Palembang | I40: FUNGSI OPERASIONAL & LAYANAN | J40: Associate | K40: KC Palembang Sriwijaya | L40: 2205 | M40: Peserta Magang
...

Sheet Sheet17
A3: Count of JOBDESC | B3: Column Labels
A4: Row Labels | B4: CUSTOMER SERVICE | C4: TELLER | D4: (blank) | E4: Grand Total
A5: 20 | B5: 1 | C5: 1 | E5: 2
A6: 59 | B6: 3 | C6: 4 | E6: 7
A7: 63 | C7: 3 | E7: 3
A8: 179 | B8: 1 | C8: 1 | E8: 2
A9: (blank)
A10: Grand Total | B10: 5 | C10: 9 | E10: 14

Sheet KK
A1: NIP | B1: JOBDESC | C1: PERNR | D1: TIPE UKER | E1: COMPLETENAME | F1: KELOMPOK JABATAN | G1: MCTEXT | H1: PADESC | I1: ORGDESC | J1: CORP. TITLE | K1: PSADESC | L1: KODE BRANCH | M1: ESGDESC
A2: K625729825 | B2: CUSTOMER SERVICE | C2: 393616 | D2: KC | E2: Devis Lucky Pratama | F2: Customer Service | G2: K_1679_KK POLTABES JAMBI | H2: Region 04 Palembang | I2: KK POLTABES JAMBI | J2: Associate | K2: KC Jambi | L2: 20 | M2: Kontrak Teller/CS
A3: 0 | B3: TELLER | C3: 408958 | D3: KC | E3: Andini Destri Aulia | F3: Teller | G3: K_1679_KK POLTABES JAMBI | H3: Region 04 Palembang | I3: KK POLTABES JAMBI | J3: Associate | K3: KC Jambi | L3: 20 | M3: Peserta Magang
A4: K600190025 | B4: CUSTOMER SERVICE | C4: 387740 | D4: KC | E4: Raudah | F4: Customer Service | G4: K_1487_KK PEMATANG LUMUT | H4: Region 04 Palembang | I4: KK PEMATANG LUMUT | J4: Associate | K4: KC Kuala Tungkal | L4: 179 | M4: Kontrak Teller/CS
A5: M303940225 | B5: TELLER | C5: 385044 | D5: KC | E5: Merdiana Ferdila | F5: Teller | G5: K_1487_KK PEMATANG LUMUT | H5: Region 04 Palembang | I5: KK PEMATANG LUMUT | J5: Associate | K5: KC Kuala Tungkal | L5: 179 | M5: Peserta Magang
A6: K319660023 | B6: CUSTOMER SERVICE | C6: 342034 | D6: KC | E6: Nabila Stephanie Putri | F6: Customer Service | G6: K_1863_KK RS PERTAMINA PLAJU | H6: Region 04 Palembang | I6: KK RS PERTAMINA PLAJU | J6: Associate | K6: KC Palembang A. Rivai | L6: 59 | M6: Kontrak Teller/CS
A7: K429209824 | B7: CUSTOMER SERVICE | C7: 359331 | D7: KC | E7: Yuni Puspita | F7: Customer Service | G7: K_1500_KK POLTABES PALEMBANG | H7: Region 04 Palembang | I7: KK POLTABES PALEMBANG | J7: Associate | K7: KC Palembang A. Rivai | L7: 59 | M7: Kontrak Teller/CS
A8: K524219925 | B8: CUSTOMER SERVICE | C8: 376536 | D8: KC | E8: Meza Bustama Sari | F8: Customer Service | G8: K_1304_KK RS CHARITAS | H8: Region 04 Palembang | I8: KK RS CHARITAS | J8: Associate | K8: KC Palembang A. Rivai | L8: 59 | M8: Kontrak Teller/CS
A9: 0 | B9: TELLER | C9: 400437 | D9: KC | E9: Rafli Bagas Aditya | F9: Teller | G9: K_1500_KK POLTABES PALEMBANG | H9: Region 04 Palembang | I9: KK POLTABES PALEMBANG | J9: Associate | K9: KC Palembang A. Rivai | L9: 59 | M9: Peserta Magang
A10: 0 | B10: TELLER | C10: 400455 | D10: KC | E10: Riski Ramadhan | F10: Teller | G10: K_1304_KK RS CHARITAS | H10: Region 04 Palembang | I10: KK RS CHARITAS | J10: Associate | K10: KC Palembang A. Rivai | L10: 59 | M10: Peserta Magang
A11: 0 | B11: TELLER | C11: 402970 | D11: KC | E11: Faturrachman | F11: Teller | G11: K_1887_KK PUSRI | H11: Region 04 Palembang | I11: KK PUSRI | J11: Associate | K11: KC Palembang A. Rivai | L11: 59 | M11: Peserta Magang
A12: 0 | B12: TELLER | C12: 409371 | D12: KC | E12: Atika Maharani Yundai | F12: Teller | G12: K_1863_KK RS PERTAMINA PLAJU | H12: Region 04 Palembang | I12: KK RS PERTAMINA PLAJU | J12: Associate | K12: KC Palembang A. Rivai | L12: 59 | M12: Peserta Magang
